Workbook

Sheet Roulement V2
B1: ROULEMENT MÉDECINS ASSOCIÉS — V2 optimisée (juillet 2026)
A3: Jour | B3: Créneau | C3: S1 Beaune | D3: S1 Dijon | E3: S2 Beaune | F3: S2 Dijon | G3: S3 Beaune | H3: S3 Dijon | I3: S4 Beaune | J3: S4 Dijon | K3: S5 Beaune | L3: S5 Dijon | M3: S6 Beaune | N3: S6 Dijon | O3: S7 Beaune | P3: S7 Dijon | Q3: S8 Beaune | R3: S8 Dijon
A4: Lundi | B4: J1 | C4: CB | E4: TE | G4: XB | I4: CB | K4: CB | O4: XB | Q4: CC
B5: J2 | C5: XB | D5: TE | E5: IEG | F5: CC | G5: IEG | I5: MY | J5: MC | L5: XB | M5: CC | N5: MY | O5: CB | P5: AS | Q5: IEG | R5: MC
B6: J3 | C6: AS | D6: MC | E6: MC | F6: MY | G6: MY | H6: AS | I6: IEG | J6: CC | K6: MC | L6: TE | M6: MC | N6: TE | O6: TE | R6: CB
B7: J4 | D7: CC | F7: XB | H7: CB | J7: AS | L7: CC | N7: XB | P7: MY | R7: AS
B8: J5
B9: J6
B10: J7 | D10: LD | F10: LD | H10: TE | J10: LD | L10: AS | N10: LD | R10: MY
B11: J8 | R11: LD
A12: Mardi | B12: J1 | E12: IEG | G12: IEG | I12: IEG | M12: IEG | O12: TE | Q12: XB
B13: J2 | C13: LD | E13: TE | F13: MC | G13: MY | H13: CC | I13: MC | L13: AS | M13: TE | N13: MC | O13: CC | P13: MC | Q13: MC | R13: CC
B14: J3 | C14: IEG | D14: CB | E14: CC | F14: CB | G14: MC | H14: TE | I14: CC | J14: AS | K14: IEG | L14: CB | M14: CC | N14: CB | O14: AS | P14: CB | Q14: MY | R14: AS
B15: J4 | D15: MY | F15: AS | H15: XB | I15: MY | J15: XB | L15: MY | M15: MY | N15: LD | P15: XB | R15: CB
B16: J5
B17: J6
B18: J7 | D18: AS | F18: LD | H18: LD | J18: LD | P18: LD | R18: LD
B19: J8
A20: Mercredi | B20: J1 | C20: MC | E20: TE | G20: TE | I20: MC | K20: MC | M20: TE | Q20: MC
B21: J2 | C21: TE | D21: AS | E21: AS | F21: CB | G21: CB | H21: AS | I21: XB | K21: IEG | L21: AS | M21: IEG | N21: AS | O21: CB | P21: CC | Q21: XB
B22: J3 | C22: IEG | E22: XB | G22: CC | I22: IEG | J22: CB | K22: TE | M22: XB | N22: CB | P22: TE | Q22: IEG | R22: AS
B23: J4 | G23: IEG | J23: AS | P23: AS
B24: J5
B25: J6
B26: J7
B27: J8
A28: Jeudi | B28: J1 | C28: TE | E28: CC | G28: CC | I28: MY | K28: IEG | M28: IEG | O28: CC
B29: J2 | C29: LD | D29: XB | E29: CB | F29: TE | G29: LD | H29: XB | I29: IEG | J29: TE | K29: XB | L29: MY | M29: AS | N29: CB | O29: MY | P29: XB | Q29: IEG | R29: TE
B30: J3 | C30: MY | D30: CC | E30: IEG | F30: XB | H30: TE | I30: XB | J30: CC | K30: TE | L30: LD | M30: XB | N30: TE | O30: TE | P30: LD | Q30: XB | R30: CB
B31: J4 | C31: IEG | D31: CB | F31: MY | H31: MY | J31: CB | L31: CB | N31: CC | R31: CC
B32: J5
B33: J6
B34: J7 | F34: LD | J34: LD | L34: CC | N34: MY | R34: LD
B35: J8
A36: vendredi | B36: J1 | C36: XB | E36: XB | G36: LD | I36: AS | K36: XB | M36: LD | Q36: AS
B37: J2 | C37: IEG | D37: MY | E37: CC | F37: MC | G37: MY | H37: MC | I37: TE | J37: CB | K37: MY | L37: LD | M37: MC | N37: CC | P37: LD | Q37: LD
B38: J3 | C38: MC | E38: MY | F38: AS | I38: MC | J38: LD | L38: MC | M38: IEG | N38: MY | O38: MC | P38: MY | Q38: TE | R38: CB
B39: J4 | E39: IEG | G39: IEG | N39: AS | R39: MC
B40: J5
B41: J6
...

Sheet Matthieu Cadennes
A1: Planning V2 — Matthieu Cadennes (MC)
A2: Roulement sur 8 semaines · lié à la feuille "Roulement V2" (mise à jour automatique)
A4: Jour | B4: S1 | C4: S2 | D4: S3 | E4: S4 | F4: S5 | G4: S6 | H4: S7 | I4: S8
A5: Lundi | B5: {=_xlfn.TEXTJOIN(" + ",TRUE,IF('Roulement V2'!C4="MC","J1 · 8h-16h · Beaune",""),IF('Roulement V2'!D4="MC","J1 · 8h-16h · Dijon",""),IF('Roulement V2'!C5="MC","J2 · 14h-22h · Beaune",""),IF('Roulement V2'!D5="MC","J2 · 14h-22h · Dijon",""),IF('Roulement V2'!C6="MC","journée · 8h-18h30 · Beaune",""),IF('Roulement V2'!D6="MC","journée · 8h-18h30 · Dijon",""),IF('Roulement V2'!C7="MC","journée · 8h-18h30 · Beaune",""),IF('Roulement V2'!D7="MC","journée · 8h-18h30 · Dijon",""),IF('Roulement V2'!C8="MC","J5 · 12h-20h · Beaune",""),IF('Roulement V2'!D8="MC","J5 · 12h-20h · Dijon",""),IF('Roulement V2'!C9="MC","préJ2/J6 · 8h-14h · Beaune",""),IF('Roulement V2'!D9="MC","préJ2/J6 · 8h-14h · Dijon",""),IF('Roulement V2'!C10="MC","journée · 8h-18h30 · Beaune",""),IF('Roulement V2'!D10="MC","journée · 8h-18h30 · Dijon",""),IF('Roulement V2'!C11="MC","journée · 8h-18h30 · Beaune",""),IF('Roulement V2'!D11="MC","journée · 8h-18h30 · Dijon",""))} -> journée · 8h-18h30 · Dijon | C5: {=_xlfn.TEXTJOIN(" + ",TRUE,IF('Roulement V2'!E4="MC","J1 · 8h-16h · Beaune",""),IF('Roulement V2'!F4="MC","J1 · 8h-16h · Dijon",""),IF('Roulement V2'!E5="MC","J2 · 14h-22h · Beaune",""),IF('Roulement V2'!F5="MC","J2 · 14h-22h · Dijon",""),IF('Roulement V2'!E6="MC","journée · 8h-18h30 · Beaune",""),IF('Roulement V2'!F6="MC","journée · 8h-18h30 · Dijon",""),IF('Roulement V2'!E7="MC","journée · 8h-18h30 · Beaune",""),IF('Roulement V2'!F7="MC","journée · 8h-18h30 · Dijon",""),IF('Roulement V2'!E8="MC","J5 · 12h-20h · Beaune",""),IF('Roulement V2'!F8="MC","J5 · 12h-20h · Dijon",""),IF('Roulement V2'!E9="MC","préJ2/J6 · 8h-14h · Beaune",""),IF('Roulement V2'!F9="MC","préJ2/J6 · 8h-14h · Dijon",""),IF('Roulement V2'!E10="MC","journée · 8h-18h30 · Beaune",""),IF('Roulement V2'!F10="MC","journée · 8h-18h30 · Dijon",""),IF('Roulement V2'!E11="MC","journée · 8h-18h30 · Beaune",""),IF('Roulement V2'!F11="MC","journée · 8h-18h30 · Dijon",""))} -> journée · 8h-18h30 · Beaune | D5: {=_xlfn.TEXTJOIN(" + ",TRUE,IF('Roulement V2'!G4="MC","J1 · 8h-16h · Beaune",""),IF('Roulement V2'!H4="MC","J1 · 8h-16h · Dijon",""),IF('Roulement V2'!G5="MC","J2 · 14h-22h · Beaune",""),IF('Roulement V2'!H5="MC","J2 · 14h-22h · Dijon",""),IF('Roulement V2'!G6="MC","journée · 8h-18h30 · Beaune",""),IF('Roulement V2'!H6="MC","journée · 8h-18h30 · Dijon",""),IF('Roulement V2'!G7="MC","journée · 8h-18h30 · Beaune",""),IF('Roulement V2'!H7="MC","journée · 8h-18h30 · Dijon",""),IF('Roulement V2'!G8="MC","J5 · 12h-20h · Beaune",""),IF('Roulement V2'!H8="MC","J5 · 12h-20h · Dijon",""),IF('Roulement V2'!G9="MC","préJ2/J6 · 8h-14h · Beaune",""),IF('Roulement V2'!H9="MC","préJ2/J6 · 8h-14h · Dijon",""),IF('Roulement V2'!G10="MC","journée · 8h-18h30 · Beaune",""),IF('Roulement V2'!H10="MC","journée · 8h-18h30 · Dijon",""),IF('Roulement V2'!G11="MC","journée · 8h-18h30 · Beaune",""),IF('Roulement V2'!H11="MC","journée · 8h-18h30 · Dijon",""))} | E5: {=_xlfn.TEXTJOIN(" + ",TRUE,IF('Roulement V2'!I4="MC","J1 · 8h-16h · Beaune",""),IF('Roulement V2'!J4="MC","J1 · 8h-16h · Dijon",""),IF('Roulement V2'!I5="MC","J2 · 14h-22h · Beaune",""),IF('Roulement V2'!J5="MC","J2 · 14h-22h · Dijon",""),IF('Roulement V2'!I6="MC","journée · 8h-18h30 · Beaune",""),IF('Roulement V2'!J6="MC","journée · 8h-18h30 · Dijon",""),IF('Roulement V2'!I7="MC","journée · 8h-18h30 · Beaune",""),IF('Roulement V2'!J7="MC","journée · 8h-18h30 · Dijon",""),IF('Roulement V2'!I8="MC","J5 · 12h-20h · Beaune",""),IF('Roulement V2'!J8="MC","J5 · 12h-20h · Dijon",""),IF('Roulement V2'!I9="MC","préJ2/J6 · 8h-14h · Beaune",""),IF('Roulement V2'!J9="MC","préJ2/J6 · 8h-14h · Dijon",""),IF('Roulement V2'!I10="MC","journée · 8h-18h30 · Beaune",""),IF('Roulement V2'!J10="MC","journée · 8h-18h30 · Dijon",""),IF('Roulement V2'!I11="MC","journée · 8h-18h30 · Beaune",""),IF('Roulement V2'!J11="MC","journée · 8h-18h30 · Dijon",""))} -> J2 · 14h-22h · Dijon | F5: {=_xlfn.TEXTJOIN(" + ",TRUE,IF('Roulement V2'!K4="MC","J1 · 8h-16h · Beaune",""),IF('Roulement V2'!L4="MC","J1 · 8h-16h · Dijon",""),IF('Roulement V2'!K5="MC","J2 · 14h-22h · Beaune",""),IF('Roulement V2'!L5="MC","J2 · 14h-22h · Dijon",""),IF('Roulement V2'!K6="MC","journée · 8h-18h30 · Beaune",""),IF('Roulement V2'!L6="MC","journée · 8h-18h30 · Dijon",""),IF('Roulement V2'!K7="MC","journée · 8h-18h30 · Beaune",""),IF('Roulement V2'!L7="MC","journée · 8h-18h30 · Dijon",""),IF('Roulement V2'!K8="MC","J5 · 12h-20h · Beaune",""),IF('Roulement V2'!L8="MC","J5 · 12h-20h · Dijon",""),IF('Roulement V2'!K9="MC","préJ2/J6 · 8h-14h · Beaune",""),IF('Roulement V2'!L9="MC","préJ2/J6 · 8h-14h · Dijon",""),IF('Roulement V2'!K10="MC","journée · 8h-18h30 · Beaune",""),IF('Roulement V2'!L10="MC","journée · 8h-18h30 · Dijon",""),IF('Roulement V2'!K11="MC","journée · 8h-18h30 · Beaune",""),IF('Roulement V2'!L11="MC","journée · 8h-18h30 · Dijon",""))} -> journée · 8h-18h30 · Beaune | G5: {=_xlfn.TEXTJOIN(" + ",TRUE,IF('Roulement V2'!M4="MC","J1 · 8h-16h · Beaune",""),IF('Roulement V2'!N4="MC","J1 · 8h-16h · Dijon",""),IF('Roulement V2'!M5="MC","J2 · 14h-22h · Beaune",""),IF('Roulement V2'!N5="MC","J2 · 14h-22h · Dijon",""),IF('Roulement V2'!M6="MC","journée · 8h-18h30 · Beaune",""),IF('Roulement V2'!N6="MC","journée · 8h-18h30 · Dijon",""),IF('Roulement V2'!M7="MC","journée · 8h-18h30 · Beaune",""),IF('Roulement V2'!N7="MC","journée · 8h-18h30 · Dijon",""),IF('Roulement V2'!M8="MC","J5 · 12h-20h · Beaune",""),IF('Roulement V2'!N8="MC","J5 · 12h-20h · Dijon",""),IF('Roulement V2'!M9="MC","préJ2/J6 · 8h-14h · Beaune",""),IF('Roulement V2'!N9="MC","préJ2/J6 · 8h-14h · Dijon",""),IF('Roulement V2'!M10="MC","journée · 8h-18h30 · Beaune",""),IF('Roulement V2'!N10="MC","journée · 8h-18h30 · Dijon",""),IF('Roulement V2'!M11="MC","journée · 8h-18h30 · Beaune",""),IF('Roulement V2'!N11="MC","journée · 8h-18h30 · Dijon",""))} -> journée · 8h-18h30 · Beaune | H5: {=_xlfn.TEXTJOIN(" + ",TRUE,IF('Roulement V2'!O4="MC","J1 · 8h-16h · Beaune",""),IF('Roulement V2'!P4="MC","J1 · 8h-16h · Dijon",""),IF('Roulement V2'!O5="MC","J2 · 14h-22h · Beaune",""),IF('Roulement V2'!P5="MC","J2 · 14h-22h · Dijon",""),IF('Roulement V2'!O6="MC","journée · 8h-18h30 · Beaune",""),IF('Roulement V2'!P6="MC","journée · 8h-18h30 · Dijon",""),IF('Roulement V2'!O7="MC","journée · 8h-18h30 · Beaune",""),IF('Roulement V2'!P7="MC","journée · 8h-18h30 · Dijon",""),IF('Roulement V2'!O8="MC","J5 · 12h-20h · Beaune",""),IF('Roulement V2'!P8="MC","J5 · 12h-20h · Dijon",""),IF('Roulement V2'!O9="MC","préJ2/J6 · 8h-14h · Beaune",""),IF('Roulement V2'!P9="MC","préJ2/J6 · 8h-14h · Dijon",""),IF('Roulement V2'!O10="MC","journée · 8h-18h30 · Beaune",""),IF('Roulement V2'!P10="MC","journée · 8h-18h30 · Dijon",""),IF('Roulement V2'!O11="MC","journée · 8h-18h30 · Beaune",""),IF('Roulement V2'!P11="MC","journée · 8h-18h30 · Dijon",""))} | I5: {=_xlfn.TEXTJOIN(" + ",TRUE,IF('Roulement V2'!Q4="MC","J1 · 8h-16h · Beaune",""),IF('Roulement V2'!R4="MC","J1 · 8h-16h · Dijon",""),IF('Roulement V2'!Q5="MC","J2 · 14h-22h · Beaune",""),IF('Roulement V2'!R5="MC","J2 · 14h-22h · Dijon",""),IF('Roulement V2'!Q6="MC","journée · 8h-18h30 · Beaune",""),IF('Roulement V2'!R6="MC","journée · 8h-18h30 · Dijon",""),IF('Roulement V2'!Q7="MC","journée · 8h-18h30 · Beaune",""),IF('Roulement V2'!R7="MC","journée · 8h-18h30 · Dijon",""),IF('Roulement V2'!Q8="MC","J5 · 12h-20h · Beaune",""),IF('Roulement V2'!R8="MC","J5 · 12h-20h · Dijon",""),IF('Roulement V2'!Q9="MC","préJ2/J6 · 8h-14h · Beaune",""),IF('Roulement V2'!R9="MC","préJ2/J6 · 8h-14h · Dijon",""),IF('Roulement V2'!Q10="MC","journée · 8h-18h30 · Beaune",""),IF('Roulement V2'!R10="MC","journée · 8h-18h30 · Dijon",""),IF('Roulement V2'!Q11="MC","journée · 8h-18h30 · Beaune",""),IF('Roulement V2'!R11="MC","journée · 8h-18h30 · Dijon",""))} -> J2 · 14h-22h · Dijon
A6: Mardi | B6: {=_xlfn.TEXTJOIN(" + ",TRUE,IF('Roulement V2'!C12="MC","J1 · 8h-16h · Beaune",""),IF('Roulement V2'!D12="MC","J1 · 8h-16h · Dijon",""),IF('Roulement V2'!C13="MC","J2 · 14h-22h · Beaune",""),IF('Roulement V2'!D13="MC","J2 · 14h-22h · Dijon",""),IF('Roulement V2'!C14="MC","journée · 8h-18h30 · Beaune",""),IF('Roulement V2'!D14="MC","journée · 8h-18h30 · Dijon",""),IF('Roulement V2'!C15="MC","journée · 8h-18h30 · Beaune",""),IF('Roulement V2'!D15="MC","journée · 8h-18h30 · Dijon",""),IF('Roulement V2'!C16="MC","J5 · 12h-20h · Beaune",""),IF('Roulement V2'!D16="MC","J5 · 12h-20h · Dijon",""),IF('Roulement V2'!C17="MC","préJ2/J6 · 8h-14h · Beaune",""),IF('Roulement V2'!D17="MC","préJ2/J6 · 8h-14h · Dijon",""),IF('Roulement V2'!C18="MC","journée · 8h-18h30 · Beaune",""),IF('Roulement V2'!D18="MC","journée · 8h-18h30 · Dijon",""),IF('Roulement V2'!C19="MC","journée · 8h-18h30 · Beaune",""),IF('Roulement V2'!D19="MC","journée · 8h-18h30 · Dijon",""))} | C6: {=_xlfn.TEXTJOIN(" + ",TRUE,IF('Roulement V2'!E12="MC","J1 · 8h-16h · Beaune",""),IF('Roulement V2'!F12="MC","J1 · 8h-16h · Dijon",""),IF('Roulement V2'!E13="MC","J2 · 14h-22h · Beaune",""),IF('Roulement V2'!F13="MC","J2 · 14h-22h · Dijon",""),IF('Roulement V2'!E14="MC","journée · 8h-18h30 · Beaune",""),IF('Roulement V2'!F14="MC","journée · 8h-18h30 · Dijon",""),IF('Roulement V2'!E15="MC","journée · 8h-18h30 · Beaune",""),IF('Roulement V2'!F15="MC","journée · 8h-18h30 · Dijon",""),IF('Roulement V2'!E16="MC","J5 · 12h-20h · Beaune",""),IF('Roulement V2'!F16="MC","J5 · 12h-20h · Dijon",""),IF('Roulement V2'!E17="MC","préJ2/J6 · 8h-14h · Beaune",""),IF('Roulement V2'!F17="MC","préJ2/J6 · 8h-14h · Dijon",""),IF('Roulement V2'!E18="MC","journée · 8h-18h30 · Beaune",""),IF('Roulement V2'!F18="MC","journée · 8h-18h30 · Dijon",""),IF('Roulement V2'!E19="MC","journée · 8h-18h30 · Beaune",""),IF('Roulement V2'!F19="MC","journée · 8h-18h30 · Dijon",""))} -> J2 · 14h-22h · Dijon | D6: {=_xlfn.TEXTJOIN(" + ",TRUE,IF('Roulement V2'!G12="MC","J1 · 8h-16h · Beaune",""),IF('Roulement V2'!H12="MC","J1 · 8h-16h · Dijon",""),IF('Roulement V2'!G13="MC","J2 · 14h-22h · Beaune",""),IF('Roulement V2'!H13="MC","J2 · 14h-22h · Dijon",""),IF('Roulement V2'!G14="MC","journée · 8h-18h30 · Beaune",""),IF('Roulement V2'!H14="MC","journée · 8h-18h30 · Dijon",""),IF('Roulement V2'!G15="MC","journée · 8h-18h30 · Beaune",""),IF('Roulement V2'!H15="MC","journée · 8h-18h30 · Dijon",""),IF('Roulement V2'!G16="MC","J5 · 12h-20h · Beaune",""),IF('Roulement V2'!H16="MC","J5 · 12h-20h · Dijon",""),IF('Roulement V2'!G17="MC","préJ2/J6 · 8h-14h · Beaune",""),IF('Roulement V2'!H17="MC","préJ2/J6 · 8h-14h · Dijon",""),IF('Roulement V2'!G18="MC","journée · 8h-18h30 · Beaune",""),IF('Roulement V2'!H18="MC","journée · 8h-18h30 · Dijon",""),IF('Roulement V2'!G19="MC","journée · 8h-18h30 · Beaune",""),IF('Roulement V2'!H19="MC","journée · 8h-18h30 · Dijon",""))} -> journée · 8h-18h30 · Beaune | E6: {=_xlfn.TEXTJOIN(" + ",TRUE,IF('Roulement V2'!I12="MC","J1 · 8h-16h · Beaune",""),IF('Roulement V2'!J12="MC","J1 · 8h-16h · Dijon",""),IF('Roulement V2'!I13="MC","J2 · 14h-22h · Beaune",""),IF('Roulement V2'!J13="MC","J2 · 14h-22h · Dijon",""),IF('Roulement V2'!I14="MC","journée · 8h-18h30 · Beaune",""),IF('Roulement V2'!J14="MC","journée · 8h-18h30 · Dijon",""),IF('Roulement V2'!I15="MC","journée · 8h-18h30 · Beaune",""),IF('Roulement V2'!J15="MC","journée · 8h-18h30 · Dijon",""),IF('Roulement V2'!I16="MC","J5 · 12h-20h · Beaune",""),IF('Roulement V2'!J16="MC","J5 · 12h-20h · Dijon",""),IF('Roulement V2'!I17="MC","préJ2/J6 · 8h-14h · Beaune",""),IF('Roulement V2'!J17="MC","préJ2/J6 · 8h-14h · Dijon",""),IF('Roulement V2'!I18="MC","journée · 8h-18h30 · Beaune",""),IF('Roulement V2'!J18="MC","journée · 8h-18h30 · Dijon",""),IF('Roulement V2'!I19="MC","journée · 8h-18h30 · Beaune",""),IF('Roulement V2'!J19="MC","journée · 8h-18h30 · Dijon",""))} -> J2 · 14h-22h · Beaune | F6: {=_xlfn.TEXTJOIN(" + ",TRUE,IF('Roulement V2'!K12="MC","J1 · 8h-16h · Beaune",""),IF('Roulement V2'!L12="MC","J1 · 8h-16h · Dijon",""),IF('Roulement V2'!K13="MC","J2 · 14h-22h · Beaune",""),IF('Roulement V2'!L13="MC","J2 · 14h-22h · Dijon",""),IF('Roulement V2'!K14="MC","journée · 8h-18h30 · Beaune",""),IF('Roulement V2'!L14="MC","journée · 8h-18h30 · Dijon",""),IF('Roulement V2'!K15="MC","journée · 8h-18h30 · Beaune",""),IF('Roulement V2'!L15="MC","journée · 8h-18h30 · Dijon",""),IF('Roulement V2'!K16="MC","J5 · 12h-20h · Beaune",""),IF('Roulement V2'!L16="MC","J5 · 12h-20h · Dijon",""),IF('Roulement V2'!K17="MC","préJ2/J6 · 8h-14h · Beaune",""),IF('Roulement V2'!L17="MC","préJ2/J6 · 8h-14h · Dijon",""),IF('Roulement V2'!K18="MC","journée · 8h-18h30 · Beaune",""),IF('Roulement V2'!L18="MC","journée · 8h-18h30 · Dijon",""),IF('Roulement V2'!K19="MC","journée · 8h-18h30 · Beaune",""),IF('Roulement V2'!L19="MC","journée · 8h-18h30 · Dijon",""))} | G6: {=_xlfn.TEXTJOIN(" + ",TRUE,IF('Roulement V2'!M12="MC","J1 · 8h-16h · Beaune",""),IF('Roulement V2'!N12="MC","J1 · 8h-16h · Dijon",""),IF('Roulement V2'!M13="MC","J2 · 14h-22h · Beaune",""),IF('Roulement V2'!N13="MC","J2 · 14h-22h · Dijon",""),IF('Roulement V2'!M14="MC","journée · 8h-18h30 · Beaune",""),IF('Roulement V2'!N14="MC","journée · 8h-18h30 · Dijon",""),IF('Roulement V2'!M15="MC","journée · 8h-18h30 · Beaune",""),IF('Roulement V2'!N15="MC","journée · 8h-18h30 · Dijon",""),IF('Roulement V2'!M16="MC","J5 · 12h-20h · Beaune",""),IF('Roulement V2'!N16="MC","J5 · 12h-20h · Dijon",""),IF('Roulement V2'!M17="MC","préJ2/J6 · 8h-14h · Beaune",""),IF('Roulement V2'!N17="MC","préJ2/J6 · 8h-14h · Dijon",""),IF('Roulement V2'!M18="MC","journée · 8h-18h30 · Beaune",""),IF('Roulement V2'!N18="MC","journée · 8h-18h30 · Dijon",""),IF('Roulement V2'!M19="MC","journée · 8h-18h30 · Beaune",""),IF('Roulement V2'!N19="MC","journée · 8h-18h30 · Dijon",""))} -> J2 · 14h-22h · Dijon | H6: {=_xlfn.TEXTJOIN(" + ",TRUE,IF('Roulement V2'!O12="MC","J1 · 8h-16h · Beaune",""),IF('Roulement V2'!P12="MC","J1 · 8h-16h · Dijon",""),IF('Roulement V2'!O13="MC","J2 · 14h-22h · Beaune",""),IF('Roulement V2'!P13="MC","J2 · 14h-22h · Dijon",""),IF('Roulement V2'!O14="MC","journée · 8h-18h30 · Beaune",""),IF('Roulement V2'!P14="MC","journée · 8h-18h30 · Dijon",""),IF('Roulement V2'!O15="MC","journée · 8h-18h30 · Beaune",""),IF('Roulement V2'!P15="MC","journée · 8h-18h30 · Dijon",""),IF('Roulement V2'!O16="MC","J5 · 12h-20h · Beaune",""),IF('Roulement V2'!P16="MC","J5 · 12h-20h · Dijon",""),IF('Roulement V2'!O17="MC","préJ2/J6 · 8h-14h · Beaune",""),IF('Roulement V2'!P17="MC","préJ2/J6 · 8h-14h · Dijon",""),IF('Roulement V2'!O18="MC","journée · 8h-18h30 · Beaune",""),IF('Roulement V2'!P18="MC","journée · 8h-18h30 · Dijon",""),IF('Roulement V2'!O19="MC","journée · 8h-18h30 · Beaune",""),IF('Roulement V2'!P19="MC","journée · 8h-18h30 · Dijon",""))} -> J2 · 14h-22h · Dijon | I6: {=_xlfn.TEXTJOIN(" + ",TRUE,IF('Roulement V2'!Q12="MC","J1 · 8h-16h · Beaune",""),IF('Roulement V2'!R12="MC","J1 · 8h-16h · Dijon",""),IF('Roulement V2'!Q13="MC","J2 · 14h-22h · Beaune",""),IF('Roulement V2'!R13="MC","J2 · 14h-22h · Dijon",""),IF('Roulement V2'!Q14="MC","journée · 8h-18h30 · Beaune",""),IF('Roulement V2'!R14="MC","journée · 8h-18h30 · Dijon",""),IF('Roulement V2'!Q15="MC","journée · 8h-18h30 · Beaune",""),IF('Roulement V2'!R15="MC","journée · 8h-18h30 · Dijon",""),IF('Roulement V2'!Q16="MC","J5 · 12h-20h · Beaune",""),IF('Roulement V2'!R16="MC","J5 · 12h-20h · Dijon",""),IF('Roulement V2'!Q17="MC","préJ2/J6 · 8h-14h · Beaune",""),IF('Roulement V2'!R17="MC","préJ2/J6 · 8h-14h · Dijon",""),IF('Roulement V2'!Q18="MC","journée · 8h-18h30 · Beaune",""),IF('Roulement V2'!R18="MC","journée · 8h-18h30 · Dijon",""),IF('Roulement V2'!Q19="MC","journée · 8h-18h30 · Beaune",""),IF('Roulement V2'!R19="MC","journée · 8h-18h30 · Dijon",""))} -> J2 · 14h-22h · Beaune
A7: Mercredi | B7: {=_xlfn.TEXTJOIN(" + ",TRUE,IF('Roulement V2'!C20="MC","J1 · 8h-16h · Beaune",""),IF('Roulement V2'!D20="MC","J1 · 8h-16h · Dijon",""),IF('Roulement V2'!C21="MC","J2 · 14h-22h · Beaune",""),IF('Roulement V2'!D21="MC","J2 · 14h-22h · Dijon",""),IF('Roulement V2'!C22="MC","journée · 8h-18h30 · Beaune",""),IF('Roulement V2'!D22="MC","journée · 8h-18h30 · Dijon",""),IF('Roulement V2'!C23="MC","journée · 8h-18h30 · Beaune",""),IF('Roulement V2'!D23="MC","journée · 8h-18h30 · Dijon",""),IF('Roulement V2'!C24="MC","J5 · 12h-20h · Beaune",""),IF('Roulement V2'!D24="MC","J5 · 12h-20h · Dijon",""),IF('Roulement V2'!C25="MC","préJ2/J6 · 8h-14h · Beaune",""),IF('Roulement V2'!D25="MC","préJ2/J6 · 8h-14h · Dijon",""),IF('Roulement V2'!C26="MC","journée · 8h-18h30 · Beaune",""),IF('Roulement V2'!D26="MC","journée · 8h-18h30 · Dijon",""),IF('Roulement V2'!C27="MC","journée · 8h-18h30 · Beaune",""),IF('Roulement V2'!D27="MC","journée · 8h-18h30 · Dijon",""))} -> J1 · 8h-16h · Beaune | C7: {=_xlfn.TEXTJOIN(" + ",TRUE,IF('Roulement V2'!E20="MC","J1 · 8h-16h · Beaune",""),IF('Roulement V2'!F20="MC","J1 · 8h-16h · Dijon",""),IF('Roulement V2'!E21="MC","J2 · 14h-22h · Beaune",""),IF('Roulement V2'!F21="MC","J2 · 14h-22h · Dijon",""),IF('Roulement V2'!E22="MC","journée · 8h-18h30 · Beaune",""),IF('Roulement V2'!F22="MC","journée · 8h-18h30 · Dijon",""),IF('Roulement V2'!E23="MC","journée · 8h-18h30 · Beaune",""),IF('Roulement V2'!F23="MC","journée · 8h-18h30 · Dijon",""),IF('Roulement V2'!E24="MC","J5 · 12h-20h · Beaune",""),IF('Roulement V2'!F24="MC","J5 · 12h-20h · Dijon",""),IF('Roulement V2'!E25="MC","préJ2/J6 · 8h-14h · Beaune",""),IF('Roulement V2'!F25="MC","préJ2/J6 · 8h-14h · Dijon",""),IF('Roulement V2'!E26="MC","journée · 8h-18h30 · Beaune",""),IF('Roulement V2'!F26="MC","journée · 8h-18h30 · Dijon",""),IF('Roulement V2'!E27="MC","journée · 8h-18h30 · Beaune",""),IF('Roulement V2'!F27="MC","journée · 8h-18h30 · Dijon",""))} | D7: {=_xlfn.TEXTJOIN(" + ",TRUE,IF('Roulement V2'!G20="MC","J1 · 8h-16h · Beaune",""),IF('Roulement V2'!H20="MC","J1 · 8h-16h · Dijon",""),IF('Roulement V2'!G21="MC","J2 · 14h-22h · Beaune",""),IF('Roulement V2'!H21="MC","J2 · 14h-22h · Dijon",""),IF('Roulement V2'!G22="MC","journée · 8h-18h30 · Beaune",""),IF('Roulement V2'!H22="MC","journée · 8h-18h30 · Dijon",""),IF('Roulement V2'!G23="MC","journée · 8h-18h30 · Beaune",""),IF('Roulement V2'!H23="MC","journée · 8h-18h30 · Dijon",""),IF('Roulement V2'!G24="MC","J5 · 12h-20h · Beaune",""),IF('Roulement V2'!H24="MC","J5 · 12h-20h · Dijon",""),IF('Roulement V2'!G25="MC","préJ2/J6 · 8h-14h · Beaune",""),IF('Roulement V2'!H25="MC","préJ2/J6 · 8h-14h · Dijon",""),IF('Roulement V2'!G26="MC","journée · 8h-18h30 · Beaune",""),IF('Roulement V2'!H26="MC","journée · 8h-18h30 · Dijon",""),IF('Roulement V2'!G27="MC","journée · 8h-18h30 · Beaune",""),IF('Roulement V2'!H27="MC","journée · 8h-18h30 · Dijon",""))} | E7: {=_xlfn.TEXTJOIN(" + ",TRUE,IF('Roulement V2'!I20="MC","J1 · 8h-16h · Beaune",""),IF('Roulement V2'!J20="MC","J1 · 8h-16h · Dijon",""),IF('Roulement V2'!I21="MC","J2 · 14h-22h · Beaune",""),IF('Roulement V2'!J21="MC","J2 · 14h-22h · Dijon",""),IF('Roulement V2'!I22="MC","journée · 8h-18h30 · Beaune",""),IF('Roulement V2'!J22="MC","journée · 8h-18h30 · Dijon",""),IF('Roulement V2'!I23="MC","journée · 8h-18h30 · Beaune",""),IF('Roulement V2'!J23="MC","journée · 8h-18h30 · Dijon",""),IF('Roulement V2'!I24="MC","J5 · 12h-20h · Beaune",""),IF('Roulement V2'!J24="MC","J5 · 12h-20h · Dijon",""),IF('Roulement V2'!I25="MC","préJ2/J6 · 8h-14h · Beaune",""),IF('Roulement V2'!J25="MC","préJ2/J6 · 8h-14h · Dijon",""),IF('Roulement V2'!I26="MC","journée · 8h-18h30 · Beaune",""),IF('Roulement V2'!J26="MC","journée · 8h-18h30 · Dijon",""),IF('Roulement V2'!I27="MC","journée · 8h-18h30 · Beaune",""),IF('Roulement V2'!J27="MC","journée · 8h-18h30 · Dijon",""))} -> J1 · 8h-16h · Beaune | F7: {=_xlfn.TEXTJOIN(" + ",TRUE,IF('Roulement V2'!K20="MC","J1 · 8h-16h · Beaune",""),IF('Roulement V2'!L20="MC","J1 · 8h-16h · Dijon",""),IF('Roulement V2'!K21="MC","J2 · 14h-22h · Beaune",""),IF('Roulement V2'!L21="MC","J2 · 14h-22h · Dijon",""),IF('Roulement V2'!K22="MC","journée · 8h-18h30 · Beaune",""),IF('Roulement V2'!L22="MC","journée · 8h-18h30 · Dijon",""),IF('Roulement V2'!K23="MC","journée · 8h-18h30 · Beaune",""),IF('Roulement V2'!L23="MC","journée · 8h-18h30 · Dijon",""),IF('Roulement V2'!K24="MC","J5 · 12h-20h · Beaune",""),IF('Roulement V2'!L24="MC","J5 · 12h-20h · Dijon",""),IF('Roulement V2'!K25="MC","préJ2/J6 · 8h-14h · Beaune",""),IF('Roulement V2'!L25="MC","préJ2/J6 · 8h-14h · Dijon",""),IF('Roulement V2'!K26="MC","journée · 8h-18h30 · Beaune",""),IF('Roulement V2'!L26="MC","journée · 8h-18h30 · Dijon",""),IF('Roulement V2'!K27="MC","journée · 8h-18h30 · Beaune",""),IF('Roulement V2'!L27="MC","journée · 8h-18h30 · Dijon",""))} -> J1 · 8h-16h · Beaune | G7: {=_xlfn.TEXTJOIN(" + ",TRUE,IF('Roulement V2'!M20="MC","J1 · 8h-16h · Beaune",""),IF('Roulement V2'!N20="MC","J1 · 8h-16h · Dijon",""),IF('Roulement V2'!M21="MC","J2 · 14h-22h · Beaune",""),IF('Roulement V2'!N21="MC","J2 · 14h-22h · Dijon",""),IF('Roulement V2'!M22="MC","journée · 8h-18h30 · Beaune",""),IF('Roulement V2'!N22="MC","journée · 8h-18h30 · Dijon",""),IF('Roulement V2'!M23="MC","journée · 8h-18h30 · Beaune",""),IF('Roulement V2'!N23="MC","journée · 8h-18h30 · Dijon",""),IF('Roulement V2'!M24="MC","J5 · 12h-20h · Beaune",""),IF('Roulement V2'!N24="MC","J5 · 12h-20h · Dijon",""),IF('Roulement V2'!M25="MC","préJ2/J6 · 8h-14h · Beaune",""),IF('Roulement V2'!N25="MC","préJ2/J6 · 8h-14h · Dijon",""),IF('Roulement V2'!M26="MC","journée · 8h-18h30 · Beaune",""),IF('Roulement V2'!N26="MC","journée · 8h-18h30 · Dijon",""),IF('Roulement V2'!M27="MC","journée · 8h-18h30 · Beaune",""),IF('Roulement V2'!N27="MC","journée · 8h-18h30 · Dijon",""))} | H7: {=_xlfn.TEXTJOIN(" + ",TRUE,IF('Roulement V2'!O20="MC","J1 · 8h-16h · Beaune",""),IF('Roulement V2'!P20="MC","J1 · 8h-16h · Dijon",""),IF('Roulement V2'!O21="MC","J2 · 14h-22h · Beaune",""),IF('Roulement V2'!P21="MC","J2 · 14h-22h · Dijon",""),IF('Roulement V2'!O22="MC","journée · 8h-18h30 · Beaune",""),IF('Roulement V2'!P22="MC","journée · 8h-18h30 · Dijon",""),IF('Roulement V2'!O23="MC","journée · 8h-18h30 · Beaune",""),IF('Roulement V2'!P23="MC","journée · 8h-18h30 · Dijon",""),IF('Roulement V2'!O24="MC","J5 · 12h-20h · Beaune",""),IF('Roulement V2'!P24="MC","J5 · 12h-20h · Dijon",""),IF('Roulement V2'!O25="MC","préJ2/J6 · 8h-14h · Beaune",""),IF('Roulement V2'!P25="MC","préJ2/J6 · 8h-14h · Dijon",""),IF('Roulement V2'!O26="MC","journée · 8h-18h30 · Beaune",""),IF('Roulement V2'!P26="MC","journée · 8h-18h30 · Dijon",""),IF('Roulement V2'!O27="MC","journée · 8h-18h30 · Beaune",""),IF('Roulement V2'!P27="MC","journée · 8h-18h30 · Dijon",""))} | I7: {=_xlfn.TEXTJOIN(" + ",TRUE,IF('Roulement V2'!Q20="MC","J1 · 8h-16h · Beaune",""),IF('Roulement V2'!R20="MC","J1 · 8h-16h · Dijon",""),IF('Roulement V2'!Q21="MC","J2 · 14h-22h · Beaune",""),IF('Roulement V2'!R21="MC","J2 · 14h-22h · Dijon",""),IF('Roulement V2'!Q22="MC","journée · 8h-18h30 · Beaune",""),IF('Roulement V2'!R22="MC","journée · 8h-18h30 · Dijon",""),IF('Roulement V2'!Q23="MC","journée · 8h-18h30 · Beaune",""),IF('Roulement V2'!R23="MC","journée · 8h-18h30 · Dijon",""),IF('Roulement V2'!Q24="MC","J5 · 12h-20h · Beaune",""),IF('Roulement V2'!R24="MC","J5 · 12h-20h · Dijon",""),IF('Roulement V2'!Q25="MC","préJ2/J6 · 8h-14h · Beaune",""),IF('Roulement V2'!R25="MC","préJ2/J6 · 8h-14h · Dijon",""),IF('Roulement V2'!Q26="MC","journée · 8h-18h30 · Beaune",""),IF('Roulement V2'!R26="MC","journée · 8h-18h30 · Dijon",""),IF('Roulement V2'!Q27="MC","journée · 8h-18h30 · Beaune",""),IF('Roulement V2'!R27="MC","journée · 8h-18h30 · Dijon",""))} -> J1 · 8h-16h · Beaune
A8: Jeudi | B8: {=_xlfn.TEXTJOIN(" + ",TRUE,IF('Roulement V2'!C28="MC","J1 · 8h-16h · Beaune",""),IF('Roulement V2'!D28="MC","J1 · 8h-16h · Dijon",""),IF('Roulement V2'!C29="MC","J2 · 14h-22h · Beaune",""),IF('Roulement V2'!D29="MC","J2 · 14h-22h · Dijon",""),IF('Roulement V2'!C30="MC","journée · 8h-18h30 · Beaune",""),IF('Roulement V2'!D30="MC","journée · 8h-18h30 · Dijon",""),IF('Roulement V2'!C31="MC","journée · 8h-18h30 · Beaune",""),IF('Roulement V2'!D31="MC","journée · 8h-18h30 · Dijon",""),IF('Roulement V2'!C32="MC","J5 · 12h-20h · Beaune",""),IF('Roulement V2'!D32="MC","J5 · 12h-20h · Dijon",""),IF('Roulement V2'!C33="MC","préJ2/J6 · 8h-14h · Beaune",""),IF('Roulement V2'!D33="MC","préJ2/J6 · 8h-14h · Dijon",""),IF('Roulement V2'!C34="MC","journée · 8h-18h30 · Beaune",""),IF('Roulement V2'!D34="MC","journée · 8h-18h30 · Dijon",""),IF('Roulement V2'!C35="MC","journée · 8h-18h30 · Beaune",""),IF('Roulement V2'!D35="MC","journée · 8h-18h30 · Dijon",""))} | C8: {=_xlfn.TEXTJOIN(" + ",TRUE,IF('Roulement V2'!E28="MC","J1 · 8h-16h · Beaune",""),IF('Roulement V2'!F28="MC","J1 · 8h-16h · Dijon",""),IF('Roulement V2'!E29="MC","J2 · 14h-22h · Beaune",""),IF('Roulement V2'!F29="MC","J2 · 14h-22h · Dijon",""),IF('Roulement V2'!E30="MC","journée · 8h-18h30 · Beaune",""),IF('Roulement V2'!F30="MC","journée · 8h-18h30 · Dijon",""),IF('Roulement V2'!E31="MC","journée · 8h-18h30 · Beaune",""),IF('Roulement V2'!F31="MC","journée · 8h-18h30 · Dijon",""),IF('Roulement V2'!E32="MC","J5 · 12h-20h · Beaune",""),IF('Roulement V2'!F32="MC","J5 · 12h-20h · Dijon",""),IF('Roulement V2'!E33="MC","préJ2/J6 · 8h-14h · Beaune",""),IF('Roulement V2'!F33="MC","préJ2/J6 · 8h-14h · Dijon",""),IF('Roulement V2'!E34="MC","journée · 8h-18h30 · Beaune",""),IF('Roulement V2'!F34="MC","journée · 8h-18h30 · Dijon",""),IF('Roulement V2'!E35="MC","journée · 8h-18h30 · Beaune",""),IF('Roulement V2'!F35="MC","journée · 8h-18h30 · Dijon",""))} | D8: {=_xlfn.TEXTJOIN(" + ",TRUE,IF('Roulement V2'!G28="MC","J1 · 8h-16h · Beaune",""),IF('Roulement V2'!H28="MC","J1 · 8h-16h · Dijon",""),IF('Roulement V2'!G29="MC","J2 · 14h-22h · Beaune",""),IF('Roulement V2'!H29="MC","J2 · 14h-22h · Dijon",""),IF('Roulement V2'!G30="MC","journée · 8h-18h30 · Beaune",""),IF('Roulement V2'!H30="MC","journée · 8h-18h30 · Dijon",""),IF('Roulement V2'!G31="MC","journée · 8h-18h30 · Beaune",""),IF('Roulement V2'!H31="MC","journée · 8h-18h30 · Dijon",""),IF('Roulement V2'!G32="MC","J5 · 12h-20h · Beaune",""),IF('Roulement V2'!H32="MC","J5 · 12h-20h · Dijon",""),IF('Roulement V2'!G33="MC","préJ2/J6 · 8h-14h · Beaune",""),IF('Roulement V2'!H33="MC","préJ2/J6 · 8h-14h · Dijon",""),IF('Roulement V2'!G34="MC","journée · 8h-18h30 · Beaune",""),IF('Roulement V2'!H34="MC","journée · 8h-18h30 · Dijon",""),IF('Roulement V2'!G35="MC","journée · 8h-18h30 · Beaune",""),IF('Roulement V2'!H35="MC","journée · 8h-18h30 · Dijon",""))} | E8: {=_xlfn.TEXTJOIN(" + ",TRUE,IF('Roulement V2'!I28="MC","J1 · 8h-16h · Beaune",""),IF('Roulement V2'!J28="MC","J1 · 8h-16h · Dijon",""),IF('Roulement V2'!I29="MC","J2 · 14h-22h · Beaune",""),IF('Roulement V2'!J29="MC","J2 · 14h-22h · Dijon",""),IF('Roulement V2'!I30="MC","journée · 8h-18h30 · Beaune",""),IF('Roulement V2'!J30="MC","journée · 8h-18h30 · Dijon",""),IF('Roulement V2'!I31="MC","journée · 8h-18h30 · Beaune",""),IF('Roulement V2'!J31="MC","journée · 8h-18h30 · Dijon",""),IF('Roulement V2'!I32="MC","J5 · 12h-20h · Beaune",""),IF('Roulement V2'!J32="MC","J5 · 12h-20h · Dijon",""),IF('Roulement V2'!I33="MC","préJ2/J6 · 8h-14h · Beaune",""),IF('Roulement V2'!J33="MC","préJ2/J6 · 8h-14h · Dijon",""),IF('Roulement V2'!I34="MC","journée · 8h-18h30 · Beaune",""),IF('Roulement V2'!J34="MC","journée · 8h-18h30 · Dijon",""),IF('Roulement V2'!I35="MC","journée · 8h-18h30 · Beaune",""),IF('Roulement V2'!J35="MC","journée · 8h-18h30 · Dijon",""))} | F8: {=_xlfn.TEXTJOIN(" + ",TRUE,IF('Roulement V2'!K28="MC","J1 · 8h-16h · Beaune",""),IF('Roulement V2'!L28="MC","J1 · 8h-16h · Dijon",""),IF('Roulement V2'!K29="MC","J2 · 14h-22h · Beaune",""),IF('Roulement V2'!L29="MC","J2 · 14h-22h · Dijon",""),IF('Roulement V2'!K30="MC","journée · 8h-18h30 · Beaune",""),IF('Roulement V2'!L30="MC","journée · 8h-18h30 · Dijon",""),IF('Roulement V2'!K31="MC","journée · 8h-18h30 · Beaune",""),IF('Roulement V2'!L31="MC","journée · 8h-18h30 · Dijon",""),IF('Roulement V2'!K32="MC","J5 · 12h-20h · Beaune",""),IF('Roulement V2'!L32="MC","J5 · 12h-20h · Dijon",""),IF('Roulement V2'!K33="MC","préJ2/J6 · 8h-14h · Beaune",""),IF('Roulement V2'!L33="MC","préJ2/J6 · 8h-14h · Dijon",""),IF('Roulement V2'!K34="MC","journée · 8h-18h30 · Beaune",""),IF('Roulement V2'!L34="MC","journée · 8h-18h30 · Dijon",""),IF('Roulement V2'!K35="MC","journée · 8h-18h30 · Beaune",""),IF('Roulement V2'!L35="MC","journée · 8h-18h30 · Dijon",""))} | G8: {=_xlfn.TEXTJOIN(" + ",TRUE,IF('Roulement V2'!M28="MC","J1 · 8h-16h · Beaune",""),IF('Roulement V2'!N28="MC","J1 · 8h-16h · Dijon",""),IF('Roulement V2'!M29="MC","J2 · 14h-22h · Beaune",""),IF('Roulement V2'!N29="MC","J2 · 14h-22h · Dijon",""),IF('Roulement V2'!M30="MC","journée · 8h-18h30 · Beaune",""),IF('Roulement V2'!N30="MC","journée · 8h-18h30 · Dijon",""),IF('Roulement V2'!M31="MC","journée · 8h-18h30 · Beaune",""),IF('Roulement V2'!N31="MC","journée · 8h-18h30 · Dijon",""),IF('Roulement V2'!M32="MC","J5 · 12h-20h · Beaune",""),IF('Roulement V2'!N32="MC","J5 · 12h-20h · Dijon",""),IF('Roulement V2'!M33="MC","préJ2/J6 · 8h-14h · Beaune",""),IF('Roulement V2'!N33="MC","préJ2/J6 · 8h-14h · Dijon",""),IF('Roulement V2'!M34="MC","journée · 8h-18h30 · Beaune",""),IF('Roulement V2'!N34="MC","journée · 8h-18h30 · Dijon",""),IF('Roulement V2'!M35="MC","journée · 8h-18h30 · Beaune",""),IF('Roulement V2'!N35="MC","journée · 8h-18h30 · Dijon",""))} | H8: {=_xlfn.TEXTJOIN(" + ",TRUE,IF('Roulement V2'!O28="MC","J1 · 8h-16h · Beaune",""),IF('Roulement V2'!P28="MC","J1 · 8h-16h · Dijon",""),IF('Roulement V2'!O29="MC","J2 · 14h-22h · Beaune",""),IF('Roulement V2'!P29="MC","J2 · 14h-22h · Dijon",""),IF('Roulement V2'!O30="MC","journée · 8h-18h30 · Beaune",""),IF('Roulement V2'!P30="MC","journée · 8h-18h30 · Dijon",""),IF('Roulement V2'!O31="MC","journée · 8h-18h30 · Beaune",""),IF('Roulement V2'!P31="MC","journée · 8h-18h30 · Dijon",""),IF('Roulement V2'!O32="MC","J5 · 12h-20h · Beaune",""),IF('Roulement V2'!P32="MC","J5 · 12h-20h · Dijon",""),IF('Roulement V2'!O33="MC","préJ2/J6 · 8h-14h · Beaune",""),IF('Roulement V2'!P33="MC","préJ2/J6 · 8h-14h · Dijon",""),IF('Roulement V2'!O34="MC","journée · 8h-18h30 · Beaune",""),IF('Roulement V2'!P34="MC","journée · 8h-18h30 · Dijon",""),IF('Roulement V2'!O35="MC","journée · 8h-18h30 · Beaune",""),IF('Roulement V2'!P35="MC","journée · 8h-18h30 · Dijon",""))} | I8: {=_xlfn.TEXTJOIN(" + ",TRUE,IF('Roulement V2'!Q28="MC","J1 · 8h-16h · Beaune",""),IF('Roulement V2'!R28="MC","J1 · 8h-16h · Dijon",""),IF('Roulement V2'!Q29="MC","J2 · 14h-22h · Beaune",""),IF('Roulement V2'!R29="MC","J2 · 14h-22h · Dijon",""),IF('Roulement V2'!Q30="MC","journée · 8h-18h30 · Beaune",""),IF('Roulement V2'!R30="MC","journée · 8h-18h30 · Dijon",""),IF('Roulement V2'!Q31="MC","journée · 8h-18h30 · Beaune",""),IF('Roulement V2'!R31="MC","journée · 8h-18h30 · Dijon",""),IF('Roulement V2'!Q32="MC","J5 · 12h-20h · Beaune",""),IF('Roulement V2'!R32="MC","J5 · 12h-20h · Dijon",""),IF('Roulement V2'!Q33="MC","préJ2/J6 · 8h-14h · Beaune",""),IF('Roulement V2'!R33="MC","préJ2/J6 · 8h-14h · Dijon",""),IF('Roulement V2'!Q34="MC","journée · 8h-18h30 · Beaune",""),IF('Roulement V2'!R34="MC","journée · 8h-18h30 · Dijon",""),IF('Roulement V2'!Q35="MC","journée · 8h-18h30 · Beaune",""),IF('Roulement V2'!R35="MC","journée · 8h-18h30 · Dijon",""))}
A9: vendredi | B9: {=_xlfn.TEXTJOIN(" + ",TRUE,IF('Roulement V2'!C36="MC","J1 · 8h-16h · Beaune",""),IF('Roulement V2'!D36="MC","J1 · 8h-16h · Dijon",""),IF('Roulement V2'!C37="MC","J2 · 14h-22h · Beaune",""),IF('Roulement V2'!D37="MC","J2 · 14h-22h · Dijon",""),IF('Roulement V2'!C38="MC","journée · 8h-18h30 · Beaune",""),IF('Roulement V2'!D38="MC","journée · 8h-18h30 · Dijon",""),IF('Roulement V2'!C39="MC","journée · 8h-18h30 · Beaune",""),IF('Roulement V2'!D39="MC","journée · 8h-18h30 · Dijon",""),IF('Roulement V2'!C40="MC","J5 · 12h-20h · Beaune",""),IF('Roulement V2'!D40="MC","J5 · 12h-20h · Dijon",""),IF('Roulement V2'!C41="MC","préJ2/J6 · 8h-14h · Beaune",""),IF('Roulement V2'!D41="MC","préJ2/J6 · 8h-14h · Dijon",""),IF('Roulement V2'!C42="MC","journée · 8h-18h30 · Beaune",""),IF('Roulement V2'!D42="MC","journée · 8h-18h30 · Dijon",""),IF('Roulement V2'!C43="MC","journée · 8h-18h30 · Beaune",""),IF('Roulement V2'!D43="MC","journée · 8h-18h30 · Dijon",""))} -> journée · 8h-18h30 · Beaune | C9: {=_xlfn.TEXTJOIN(" + ",TRUE,IF('Roulement V2'!E36="MC","J1 · 8h-16h · Beaune",""),IF('Roulement V2'!F36="MC","J1 · 8h-16h · Dijon",""),IF('Roulement V2'!E37="MC","J2 · 14h-22h · Beaune",""),IF('Roulement V2'!F37="MC","J2 · 14h-22h · Dijon",""),IF('Roulement V2'!E38="MC","journée · 8h-18h30 · Beaune",""),IF('Roulement V2'!F38="MC","journée · 8h-18h30 · Dijon",""),IF('Roulement V2'!E39="MC","journée · 8h-18h30 · Beaune",""),IF('Roulement V2'!F39="MC","journée · 8h-18h30 · Dijon",""),IF('Roulement V2'!E40="MC","J5 · 12h-20h · Beaune",""),IF('Roulement V2'!F40="MC","J5 · 12h-20h · Dijon",""),IF('Roulement V2'!E41="MC","préJ2/J6 · 8h-14h · Beaune",""),IF('Roulement V2'!F41="MC","préJ2/J6 · 8h-14h · Dijon",""),IF('Roulement V2'!E42="MC","journée · 8h-18h30 · Beaune",""),IF('Roulement V2'!F42="MC","journée · 8h-18h30 · Dijon",""),IF('Roulement V2'!E43="MC","journée · 8h-18h30 · Beaune",""),IF('Roulement V2'!F43="MC","journée · 8h-18h30 · Dijon",""))} -> J2 · 14h-22h · Dijon | D9: {=_xlfn.TEXTJOIN(" + ",TRUE,IF('Roulement V2'!G36="MC","J1 · 8h-16h · Beaune",""),IF('Roulement V2'!H36="MC","J1 · 8h-16h · Dijon",""),IF('Roulement V2'!G37="MC","J2 · 14h-22h · Beaune",""),IF('Roulement V2'!H37="MC","J2 · 14h-22h · Dijon",""),IF('Roulement V2'!G38="MC","journée · 8h-18h30 · Beaune",""),IF('Roulement V2'!H38="MC","journée · 8h-18h30 · Dijon",""),IF('Roulement V2'!G39="MC","journée · 8h-18h30 · Beaune",""),IF('Roulement V2'!H39="MC","journée · 8h-18h30 · Dijon",""),IF('Roulement V2'!G40="MC","J5 · 12h-20h · Beaune",""),IF('Roulement V2'!H40="MC","J5 · 12h-20h · Dijon",""),IF('Roulement V2'!G41="MC","préJ2/J6 · 8h-14h · Beaune",""),IF('Roulement V2'!H41="MC","préJ2/J6 · 8h-14h · Dijon",""),IF('Roulement V2'!G42="MC","journée · 8h-18h30 · Beaune",""),IF('Roulement V2'!H42="MC","journée · 8h-18h30 · Dijon",""),IF('Roulement V2'!G43="MC","journée · 8h-18h30 · Beaune",""),IF('Roulement V2'!H43="MC","journée · 8h-18h30 · Dijon",""))} -> J2 · 14h-22h · Dijon | E9: {=_xlfn.TEXTJOIN(" + ",TRUE,IF('Roulement V2'!I36="MC","J1 · 8h-16h · Beaune",""),IF('Roulement V2'!J36="MC","J1 · 8h-16h · Dijon",""),IF('Roulement V2'!I37="MC","J2 · 14h-22h · Beaune",""),IF('Roulement V2'!J37="MC","J2 · 14h-22h · Dijon",""),IF('Roulement V2'!I38="MC","journée · 8h-18h30 · Beaune",""),IF('Roulement V2'!J38="MC","journée · 8h-18h30 · Dijon",""),IF('Roulement V2'!I39="MC","journée · 8h-18h30 · Beaune",""),IF('Roulement V2'!J39="MC","journée · 8h-18h30 · Dijon",""),IF('Roulement V2'!I40="MC","J5 · 12h-20h · Beaune",""),IF('Roulement V2'!J40="MC","J5 · 12h-20h · Dijon",""),IF('Roulement V2'!I41="MC","préJ2/J6 · 8h-14h · Beaune",""),IF('Roulement V2'!J41="MC","préJ2/J6 · 8h-14h · Dijon",""),IF('Roulement V2'!I42="MC","journée · 8h-18h30 · Beaune",""),IF('Roulement V2'!J42="MC","journée · 8h-18h30 · Dijon",""),IF('Roulement V2'!I43="MC","journée · 8h-18h30 · Beaune",""),IF('Roulement V2'!J43="MC","journée · 8h-18h30 · Dijon",""))} -> journée · 8h-18h30 · Beaune | F9: {=_xlfn.TEXTJOIN(" + ",TRUE,IF('Roulement V2'!K36="MC","J1 · 8h-16h · Beaune",""),IF('Roulement V2'!L36="MC","J1 · 8h-16h · Dijon",""),IF('Roulement V2'!K37="MC","J2 · 14h-22h · Beaune",""),IF('Roulement V2'!L37="MC","J2 · 14h-22h · Dijon",""),IF('Roulement V2'!K38="MC","journée · 8h-18h30 · Beaune",""),IF('Roulement V2'!L38="MC","journée · 8h-18h30 · Dijon",""),IF('Roulement V2'!K39="MC","journée · 8h-18h30 · Beaune",""),IF('Roulement V2'!L39="MC","journée · 8h-18h30 · Dijon",""),IF('Roulement V2'!K40="MC","J5 · 12h-20h · Beaune",""),IF('Roulement V2'!L40="MC","J5 · 12h-20h · Dijon",""),IF('Roulement V2'!K41="MC","préJ2/J6 · 8h-14h · Beaune",""),IF('Roulement V2'!L41="MC","préJ2/J6 · 8h-14h · Dijon",""),IF('Roulement V2'!K42="MC","journée · 8h-18h30 · Beaune",""),IF('Roulement V2'!L42="MC","journée · 8h-18h30 · Dijon",""),IF('Roulement V2'!K43="MC","journée · 8h-18h30 · Beaune",""),IF('Roulement V2'!L43="MC","journée · 8h-18h30 · Dijon",""))} -> journée · 8h-18h30 · Dijon | G9: {=_xlfn.TEXTJOIN(" + ",TRUE,IF('Roulement V2'!M36="MC","J1 · 8h-16h · Beaune",""),IF('Roulement V2'!N36="MC","J1 · 8h-16h · Dijon",""),IF('Roulement V2'!M37="MC","J2 · 14h-22h · Beaune",""),IF('Roulement V2'!N37="MC","J2 · 14h-22h · Dijon",""),IF('Roulement V2'!M38="MC","journée · 8h-18h30 · Beaune",""),IF('Roulement V2'!N38="MC","journée · 8h-18h30 · Dijon",""),IF('Roulement V2'!M39="MC","journée · 8h-18h30 · Beaune",""),IF('Roulement V2'!N39="MC","journée · 8h-18h30 · Dijon",""),IF('Roulement V2'!M40="MC","J5 · 12h-20h · Beaune",""),IF('Roulement V2'!N40="MC","J5 · 12h-20h · Dijon",""),IF('Roulement V2'!M41="MC","préJ2/J6 · 8h-14h · Beaune",""),IF('Roulement V2'!N41="MC","préJ2/J6 · 8h-14h · Dijon",""),IF('Roulement V2'!M42="MC","journée · 8h-18h30 · Beaune",""),IF('Roulement V2'!N42="MC","journée · 8h-18h30 · Dijon",""),IF('Roulement V2'!M43="MC","journée · 8h-18h30 · Beaune",""),IF('Roulement V2'!N43="MC","journée · 8h-18h30 · Dijon",""))} -> J2 · 14h-22h · Beaune | H9: {=_xlfn.TEXTJOIN(" + ",TRUE,IF('Roulement V2'!O36="MC","J1 · 8h-16h · Beaune",""),IF('Roulement V2'!P36="MC","J1 · 8h-16h · Dijon",""),IF('Roulement V2'!O37="MC","J2 · 14h-22h · Beaune",""),IF('Roulement V2'!P37="MC","J2 · 14h-22h · Dijon",""),IF('Roulement V2'!O38="MC","journée · 8h-18h30 · Beaune",""),IF('Roulement V2'!P38="MC","journée · 8h-18h30 · Dijon",""),IF('Roulement V2'!O39="MC","journée · 8h-18h30 · Beaune",""),IF('Roulement V2'!P39="MC","journée · 8h-18h30 · Dijon",""),IF('Roulement V2'!O40="MC","J5 · 12h-20h · Beaune",""),IF('Roulement V2'!P40="MC","J5 · 12h-20h · Dijon",""),IF('Roulement V2'!O41="MC","préJ2/J6 · 8h-14h · Beaune",""),IF('Roulement V2'!P41="MC","préJ2/J6 · 8h-14h · Dijon",""),IF('Roulement V2'!O42="MC","journée · 8h-18h30 · Beaune",""),IF('Roulement V2'!P42="MC","journée · 8h-18h30 · Dijon",""),IF('Roulement V2'!O43="MC","journée · 8h-18h30 · Beaune",""),IF('Roulement V2'!P43="MC","journée · 8h-18h30 · Dijon",""))} -> journée · 8h-18h30 · Beaune | I9: {=_xlfn.TEXTJOIN(" + ",TRUE,IF('Roulement V2'!Q36="MC","J1 · 8h-16h · Beaune",""),IF('Roulement V2'!R36="MC","J1 · 8h-16h · Dijon",""),IF('Roulement V2'!Q37="MC","J2 · 14h-22h · Beaune",""),IF('Roulement V2'!R37="MC","J2 · 14h-22h · Dijon",""),IF('Roulement V2'!Q38="MC","journée · 8h-18h30 · Beaune",""),IF('Roulement V2'!R38="MC","journée · 8h-18h30 · Dijon",""),IF('Roulement V2'!Q39="MC","journée · 8h-18h30 · Beaune",""),IF('Roulement V2'!R39="MC","journée · 8h-18h30 · Dijon",""),IF('Roulement V2'!Q40="MC","J5 · 12h-20h · Beaune",""),IF('Roulement V2'!R40="MC","J5 · 12h-20h · Dijon",""),IF('Roulement V2'!Q41="MC","préJ2/J6 · 8h-14h · Beaune",""),IF('Roulement V2'!R41="MC","préJ2/J6 · 8h-14h · Dijon",""),IF('Roulement V2'!Q42="MC","journée · 8h-18h30 · Beaune",""),IF('Roulement V2'!R42="MC","journée · 8h-18h30 · Dijon",""),IF('Roulement V2'!Q43="MC","journée · 8h-18h30 · Beaune",""),IF('Roulement V2'!R43="MC","journée · 8h-18h30 · Dijon",""))} -> journée · 8h-18h30 · Dijon
A10: Samedi | B10: {=_xlfn.TEXTJOIN(" + ",TRUE,IF('Roulement V2'!C44="MC","Garde · Beaune",""),IF('Roulement V2'!D44="MC","Garde · Dijon",""),IF('Roulement V2'!C45="MC","Doublon · Beaune",""),IF('Roulement V2'!D45="MC","Doublon · Dijon",""))} | C10: {=_xlfn.TEXTJOIN(" + ",TRUE,IF('Roulement V2'!E44="MC","Garde · Beaune",""),IF('Roulement V2'!F44="MC","Garde · Dijon",""),IF('Roulement V2'!E45="MC","Doublon · Beaune",""),IF('Roulement V2'!F45="MC","Doublon · Dijon",""))} -> Garde · Dijon | D10: {=_xlfn.TEXTJOIN(" + ",TRUE,IF('Roulement V2'!G44="MC","Garde · Beaune",""),IF('Roulement V2'!H44="MC","Garde · Dijon",""),IF('Roulement V2'!G45="MC","Doublon · Beaune",""),IF('Roulement V2'!H45="MC","Doublon · Dijon",""))} | E10: {=_xlfn.TEXTJOIN(" + ",TRUE,IF('Roulement V2'!I44="MC","Garde · Beaune",""),IF('Roulement V2'!J44="MC","Garde · Dijon",""),IF('Roulement V2'!I45="MC","Doublon · Beaune",""),IF('Roulement V2'!J45="MC","Doublon · Dijon",""))} | F10: {=_xlfn.TEXTJOIN(" + ",TRUE,IF('Roulement V2'!K44="MC","Garde · Beaune",""),IF('Roulement V2'!L44="MC","Garde · Dijon",""),IF('Roulement V2'!K45="MC","Doublon · Beaune",""),IF('Roulement V2'!L45="MC","Doublon · Dijon",""))} | G10: {=_xlfn.TEXTJOIN(" + ",TRUE,IF('Roulement V2'!M44="MC","Garde · Beaune",""),IF('Roulement V2'!N44="MC","Garde · Dijon",""),IF('Roulement V2'!M45="MC","Doublon · Beaune",""),IF('Roulement V2'!N45="MC","Doublon · Dijon",""))} -> Garde · Beaune | H10: {=_xlfn.TEXTJOIN(" + ",TRUE,IF('Roulement V2'!O44="MC","Garde · Beaune",""),IF('Roulement V2'!P44="MC","Garde · Dijon",""),IF('Roulement V2'!O45="MC","Doublon · Beaune",""),IF('Roulement V2'!P45="MC","Doublon · Dijon",""))} | I10: {=_xlfn.TEXTJOIN(" + ",TRUE,IF('Roulement V2'!Q44="MC","Garde · Beaune",""),IF('Roulement V2'!R44="MC","Garde · Dijon",""),IF('Roulement V2'!Q45="MC","Doublon · Beaune",""),IF('Roulement V2'!R45="MC","Doublon · Dijon",""))}
A11: Dimanche | B11: {=_xlfn.TEXTJOIN(" + ",TRUE,IF('Roulement V2'!C46="MC","Garde · Beaune",""),IF('Roulement V2'!D46="MC","Garde · Dijon",""),IF('Roulement V2'!C47="MC","Doublon · Beaune",""),IF('Roulement V2'!D47="MC","Doublon · Dijon",""))} | C11: {=_xlfn.TEXTJOIN(" + ",TRUE,IF('Roulement V2'!E46="MC","Garde · Beaune",""),IF('Roulement V2'!F46="MC","Garde · Dijon",""),IF('Roulement V2'!E47="MC","Doublon · Beaune",""),IF('Roulement V2'!F47="MC","Doublon · Dijon",""))} -> Garde · Dijon | D11: {=_xlfn.TEXTJOIN(" + ",TRUE,IF('Roulement V2'!G46="MC","Garde · Beaune",""),IF('Roulement V2'!H46="MC","Garde · Dijon",""),IF('Roulement V2'!G47="MC","Doublon · Beaune",""),IF('Roulement V2'!H47="MC","Doublon · Dijon",""))} | E11: {=_xlfn.TEXTJOIN(" + ",TRUE,IF('Roulement V2'!I46="MC","Garde · Beaune",""),IF('Roulement V2'!J46="MC","Garde · Dijon",""),IF('Roulement V2'!I47="MC","Doublon · Beaune",""),IF('Roulement V2'!J47="MC","Doublon · Dijon",""))} | F11: {=_xlfn.TEXTJOIN(" + ",TRUE,IF('Roulement V2'!K46="MC","Garde · Beaune",""),IF('Roulement V2'!L46="MC","Garde · Dijon",""),IF('Roulement V2'!K47="MC","Doublon · Beaune",""),IF('Roulement V2'!L47="MC","Doublon · Dijon",""))} | G11: {=_xlfn.TEXTJOIN(" + ",TRUE,IF('Roulement V2'!M46="MC","Garde · Beaune",""),IF('Roulement V2'!N46="MC","Garde · Dijon",""),IF('Roulement V2'!M47="MC","Doublon · Beaune",""),IF('Roulement V2'!N47="MC","Doublon · Dijon",""))} -> Garde · Beaune | H11: {=_xlfn.TEXTJOIN(" + ",TRUE,IF('Roulement V2'!O46="MC","Garde · Beaune",""),IF('Roulement V2'!P46="MC","Garde · Dijon",""),IF('Roulement V2'!O47="MC","Doublon · Beaune",""),IF('Roulement V2'!P47="MC","Doublon · Dijon",""))} | I11: {=_xlfn.TEXTJOIN(" + ",TRUE,IF('Roulement V2'!Q46="MC","Garde · Beaune",""),IF('Roulement V2'!R46="MC","Garde · Dijon",""),IF('Roulement V2'!Q47="MC","Doublon · Beaune",""),IF('Roulement V2'!R47="MC","Doublon · Dijon",""))}
A14: Récapitulatif — sur 8 semaines (mise à jour automatique)
A15: J1 · 8h-16h | B15: {=COUNTIF(B5:I9,"*J1 · 8h-16h*")} -> 4 | D15: Beaune | E15: {=COUNTIF(B5:I9,"*Beaune*")} -> 14
A16: J2 · 14h-22h | B16: {=COUNTIF(B5:I9,"*J2 · 14h-22h*")} -> 10 | D16: Dijon | E16: {=COUNTIF(B5:I9,"*Dijon*")} -> 10
A17: Journée · 8h-18h30 | B17: {=COUNTIF(B5:I9,"*journée · 8h-18h30*")} -> 10
A18: Total semaine | B18: {=COUNTIF(B5:I9,"?*")} -> 24 | D18: Gardes WE | E18: {=COUNTIF(B10:I11,"*Garde*")} -> 4
D19: Doublons WE | E19: {=COUNTIF(B10:I11,"*Doublon*")} -> 0

Sheet Caroline Chauvet
A1: Planning V2 — Caroline Chauvet (CC)
A2: Roulement sur 8 semaines · lié à la feuille "Roulement V2" (mise à jour automatique)
A4: Jour | B4: S1 | C4: S2 | D4: S3 | E4: S4 | F4: S5 | G4: S6 | H4: S7 | I4: S8
A5: Lundi | B5: {=_xlfn.TEXTJOIN(" + ",TRUE,IF('Roulement V2'!C4="CC","J1 · 8h-16h · Beaune",""),IF('Roulement V2'!D4="CC","J1 · 8h-16h · Dijon",""),IF('Roulement V2'!C5="CC","J2 · 14h-22h · Beaune",""),IF('Roulement V2'!D5="CC","J2 · 14h-22h · Dijon",""),IF('Roulement V2'!C6="CC","journée · 8h-18h30 · Beaune",""),IF('Roulement V2'!D6="CC","journée · 8h-18h30 · Dijon",""),IF('Roulement V2'!C7="CC","journée · 8h-18h30 · Beaune",""),IF('Roulement V2'!D7="CC","journée · 8h-18h30 · Dijon",""),IF('Roulement V2'!C8="CC","J5 · 12h-20h · Beaune",""),IF('Roulement V2'!D8="CC","J5 · 12h-20h · Dijon",""),IF('Roulement V2'!C9="CC","préJ2/J6 · 8h-14h · Beaune",""),IF('Roulement V2'!D9="CC","préJ2/J6 · 8h-14h · Dijon",""),IF('Roulement V2'!C10="CC","journée · 8h-18h30 · Beaune",""),IF('Roulement V2'!D10="CC","journée · 8h-18h30 · Dijon",""),IF('Roulement V2'!C11="CC","journée · 8h-18h30 · Beaune",""),IF('Roulement V2'!D11="CC","journée · 8h-18h30 · Dijon",""))} -> journée · 8h-18h30 · Dijon | C5: {=_xlfn.TEXTJOIN(" + ",TRUE,IF('Roulement V2'!E4="CC","J1 · 8h-16h · Beaune",""),IF('Roulement V2'!F4="CC","J1 · 8h-16h · Dijon",""),IF('Roulement V2'!E5="CC","J2 · 14h-22h · Beaune",""),IF('Roulement V2'!F5="CC","J2 · 14h-22h · Dijon",""),IF('Roulement V2'!E6="CC","journée · 8h-18h30 · Beaune",""),IF('Roulement V2'!F6="CC","journée · 8h-18h30 · Dijon",""),IF('Roulement V2'!E7="CC","journée · 8h-18h30 · Beaune",""),IF('Roulement V2'!F7="CC","journée · 8h-18h30 · Dijon",""),IF('Roulement V2'!E8="CC","J5 · 12h-20h · Beaune",""),IF('Roulement V2'!F8="CC","J5 · 12h-20h · Dijon",""),IF('Roulement V2'!E9="CC","préJ2/J6 · 8h-14h · Beaune",""),IF('Roulement V2'!F9="CC","préJ2/J6 · 8h-14h · Dijon",""),IF('Roulement V2'!E10="CC","journée · 8h-18h30 · Beaune",""),IF('Roulement V2'!F10="CC","journée · 8h-18h30 · Dijon",""),IF('Roulement V2'!E11="CC","journée · 8h-18h30 · Beaune",""),IF('Roulement V2'!F11="CC","journée · 8h-18h30 · Dijon",""))} -> J2 · 14h-22h · Dijon | D5: {=_xlfn.TEXTJOIN(" + ",TRUE,IF('Roulement V2'!G4="CC","J1 · 8h-16h · Beaune",""),IF('Roulement V2'!H4="CC","J1 · 8h-16h · Dijon",""),IF('Roulement V2'!G5="CC","J2 · 14h-22h · Beaune",""),IF('Roulement V2'!H5="CC","J2 · 14h-22h · Dijon",""),IF('Roulement V2'!G6="CC","journée · 8h-18h30 · Beaune",""),IF('Roulement V2'!H6="CC","journée · 8h-18h30 · Dijon",""),IF('Roulement V2'!G7="CC","journée · 8h-18h30 · Beaune",""),IF('Roulement V2'!H7="CC","journée · 8h-18h30 · Dijon",""),IF('Roulement V2'!G8="CC","J5 · 12h-20h · Beaune",""),IF('Roulement V2'!H8="CC","J5 · 12h-20h · Dijon",""),IF('Roulement V2'!G9="CC","préJ2/J6 · 8h-14h · Beaune",""),IF('Roulement V2'!H9="CC","préJ2/J6 · 8h-14h · Dijon",""),IF('Roulement V2'!G10="CC","journée · 8h-18h30 · Beaune",""),IF('Roulement V2'!H10="CC","journée · 8h-18h30 · Dijon",""),IF('Roulement V2'!G11="CC","journée · 8h-18h30 · Beaune",""),IF('Roulement V2'!H11="CC","journée · 8h-18h30 · Dijon",""))} | E5: {=_xlfn.TEXTJOIN(" + ",TRUE,IF('Roulement V2'!I4="CC","J1 · 8h-16h · Beaune",""),IF('Roulement V2'!J4="CC","J1 · 8h-16h · Dijon",""),IF('Roulement V2'!I5="CC","J2 · 14h-22h · Beaune",""),IF('Roulement V2'!J5="CC","J2 · 14h-22h · Dijon",""),IF('Roulement V2'!I6="CC","journée · 8h-18h30 · Beaune",""),IF('Roulement V2'!J6="CC","journée · 8h-18h30 · Dijon",""),IF('Roulement V2'!I7="CC","journée · 8h-18h30 · Beaune",""),IF('Roulement V2'!J7="CC","journée · 8h-18h30 · Dijon",""),IF('Roulement V2'!I8="CC","J5 · 12h-20h · Beaune",""),IF('Roulement V2'!J8="CC","J5 · 12h-20h · Dijon",""),IF('Roulement V2'!I9="CC","préJ2/J6 · 8h-14h · Beaune",""),IF('Roulement V2'!J9="CC","préJ2/J6 · 8h-14h · Dijon",""),IF('Roulement V2'!I10="CC","journée · 8h-18h30 · Beaune",""),IF('Roulement V2'!J10="CC","journée · 8h-18h30 · Dijon",""),IF('Roulement V2'!I11="CC","journée · 8h-18h30 · Beaune",""),IF('Roulement V2'!J11="CC","journée · 8h-18h30 · Dijon",""))} -> journée · 8h-18h30 · Dijon | F5: {=_xlfn.TEXTJOIN(" + ",TRUE,IF('Roulement V2'!K4="CC","J1 · 8h-16h · Beaune",""),IF('Roulement V2'!L4="CC","J1 · 8h-16h · Dijon",""),IF('Roulement V2'!K5="CC","J2 · 14h-22h · Beaune",""),IF('Roulement V2'!L5="CC","J2 · 14h-22h · Dijon",""),IF('Roulement V2'!K6="CC","journée · 8h-18h30 · Beaune",""),IF('Roulement V2'!L6="CC","journée · 8h-18h30 · Dijon",""),IF('Roulement V2'!K7="CC","journée · 8h-18h30 · Beaune",""),IF('Roulement V2'!L7="CC","journée · 8h-18h30 · Dijon",""),IF('Roulement V2'!K8="CC","J5 · 12h-20h · Beaune",""),IF('Roulement V2'!L8="CC","J5 · 12h-20h · Dijon",""),IF('Roulement V2'!K9="CC","préJ2/J6 · 8h-14h · Beaune",""),IF('Roulement V2'!L9="CC","préJ2/J6 · 8h-14h · Dijon",""),IF('Roulement V2'!K10="CC","journée · 8h-18h30 · Beaune",""),IF('Roulement V2'!L10="CC","journée · 8h-18h30 · Dijon",""),IF('Roulement V2'!K11="CC","journée · 8h-18h30 · Beaune",""),IF('Roulement V2'!L11="CC","journée · 8h-18h30 · Dijon",""))} -> journée · 8h-18h30 · Dijon | G5: {=_xlfn.TEXTJOIN(" + ",TRUE,IF('Roulement V2'!M4="CC","J1 · 8h-16h · Beaune",""),IF('Roulement V2'!N4="CC","J1 · 8h-16h · Dijon",""),IF('Roulement V2'!M5="CC","J2 · 14h-22h · Beaune",""),IF('Roulement V2'!N5="CC","J2 · 14h-22h · Dijon",""),IF('Roulement V2'!M6="CC","journée · 8h-18h30 · Beaune",""),IF('Roulement V2'!N6="CC","journée · 8h-18h30 · Dijon",""),IF('Roulement V2'!M7="CC","journée · 8h-18h30 · Beaune",""),IF('Roulement V2'!N7="CC","journée · 8h-18h30 · Dijon",""),IF('Roulement V2'!M8="CC","J5 · 12h-20h · Beaune",""),IF('Roulement V2'!N8="CC","J5 · 12h-20h · Dijon",""),IF('Roulement V2'!M9="CC","préJ2/J6 · 8h-14h · Beaune",""),IF('Roulement V2'!N9="CC","préJ2/J6 · 8h-14h · Dijon",""),IF('Roulement V2'!M10="CC","journée · 8h-18h30 · Beaune",""),IF('Roulement V2'!N10="CC","journée · 8h-18h30 · Dijon",""),IF('Roulement V2'!M11="CC","journée · 8h-18h30 · Beaune",""),IF('Roulement V2'!N11="CC","journée · 8h-18h30 · Dijon",""))} -> J2 · 14h-22h · Beaune | H5: {=_xlfn.TEXTJOIN(" + ",TRUE,IF('Roulement V2'!O4="CC","J1 · 8h-16h · Beaune",""),IF('Roulement V2'!P4="CC","J1 · 8h-16h · Dijon",""),IF('Roulement V2'!O5="CC","J2 · 14h-22h · Beaune",""),IF('Roulement V2'!P5="CC","J2 · 14h-22h · Dijon",""),IF('Roulement V2'!O6="CC","journée · 8h-18h30 · Beaune",""),IF('Roulement V2'!P6="CC","journée · 8h-18h30 · Dijon",""),IF('Roulement V2'!O7="CC","journée · 8h-18h30 · Beaune",""),IF('Roulement V2'!P7="CC","journée · 8h-18h30 · Dijon",""),IF('Roulement V2'!O8="CC","J5 · 12h-20h · Beaune",""),IF('Roulement V2'!P8="CC","J5 · 12h-20h · Dijon",""),IF('Roulement V2'!O9="CC","préJ2/J6 · 8h-14h · Beaune",""),IF('Roulement V2'!P9="CC","préJ2/J6 · 8h-14h · Dijon",""),IF('Roulement V2'!O10="CC","journée · 8h-18h30 · Beaune",""),IF('Roulement V2'!P10="CC","journée · 8h-18h30 · Dijon",""),IF('Roulement V2'!O11="CC","journée · 8h-18h30 · Beaune",""),IF('Roulement V2'!P11="CC","journée · 8h-18h30 · Dijon",""))} | I5: {=_xlfn.TEXTJOIN(" + ",TRUE,IF('Roulement V2'!Q4="CC","J1 · 8h-16h · Beaune",""),IF('Roulement V2'!R4="CC","J1 · 8h-16h · Dijon",""),IF('Roulement V2'!Q5="CC","J2 · 14h-22h · Beaune",""),IF('Roulement V2'!R5="CC","J2 · 14h-22h · Dijon",""),IF('Roulement V2'!Q6="CC","journée · 8h-18h30 · Beaune",""),IF('Roulement V2'!R6="CC","journée · 8h-18h30 · Dijon",""),IF('Roulement V2'!Q7="CC","journée · 8h-18h30 · Beaune",""),IF('Roulement V2'!R7="CC","journée · 8h-18h30 · Dijon",""),IF('Roulement V2'!Q8="CC","J5 · 12h-20h · Beaune",""),IF('Roulement V2'!R8="CC","J5 · 12h-20h · Dijon",""),IF('Roulement V2'!Q9="CC","préJ2/J6 · 8h-14h · Beaune",""),IF('Roulement V2'!R9="CC","préJ2/J6 · 8h-14h · Dijon",""),IF('Roulement V2'!Q10="CC","journée · 8h-18h30 · Beaune",""),IF('Roulement V2'!R10="CC","journée · 8h-18h30 · Dijon",""),IF('Roulement V2'!Q11="CC","journée · 8h-18h30 · Beaune",""),IF('Roulement V2'!R11="CC","journée · 8h-18h30 · Dijon",""))} -> J1 · 8h-16h · Beaune
