Workbook

Sheet Roulement V2
B1: ROULEMENT MÉDECINS ASSOCIÉS — V2 optimisée (Octobre 2026)
A3: Jour | B3: Créneau | C3: S1 Beaune | D3: S1 Dijon | E3: S2 Beaune | F3: S2 Dijon | G3: S3 Beaune | H3: S3 Dijon | I3: S4 Beaune | J3: S4 Dijon | K3: S5 Beaune | L3: S5 Dijon | M3: S6 Beaune | N3: S6 Dijon | O3: S7 Beaune | P3: S7 Dijon | Q3: S8 Beaune | R3: S8 Dijon
A4: Lundi | B4: J1 | C4: CB | E4: TE | G4: XB | I4: CB | K4: CB | O4: XB | Q4: CC
B5: J2 | C5: XB | D5: TE | E5: IEG | F5: CC | G5: IEG | I5: MY | J5: MC | L5: XB | M5: CC | N5: MY | O5: CB | P5: AS | Q5: IEG | R5: MC
B6: J3 | C6: AS | D6: MC | E6: MC | F6: MY | G6: MY | H6: AS | I6: IEG | J6: CC | K6: MC | L6: TE | M6: MC | N6: TE | O6: TE | R6: CB
B7: J4 | C7: IEG | D7: CC | F7: XB | H7: CB | J7: AS | K7: LD | L7: CC | N7: XB | P7: MY | R7: AS
B8: J6
B9: J7 | D9: LD | F9: LD | H9: TE | J9: LD | L9: AS | N9: LD | R9: MY
B10: J8 | R10: LD
A11: Mardi | B11: J1 | E11: IEG | G11: XB | I11: MY | M11: IEG | O11: TE | Q11: XB
B12: J2 | E12: TE | F12: MC | G12: MY | H12: CC | I12: MC | K12: IEG | M12: TE | N12: MC | O12: CC | P12: MC | Q12: MC | R12: CC
B13: J3 | C13: IEG | D13: CB | E13: CC | F13: CB | G13: MC | H13: TE | I13: CC | J13: AS | L13: CB | M13: CC | N13: CB | O13: AS | P13: CB | Q13: MY | R13: AS
B14: J4 | D14: MY | F14: AS | G14: IEG | I14: IEG | J14: XB | L14: MY | M14: MY | N14: LD | P14: XB | Q14: IEG | R14: CB
B15: J6
B16: J7 | D16: AS | F16: LD | H16: LD | J16: LD | L16: LD | P16: LD | R16: LD
B17: J8 | D17: LD | L17: AS
A18: Mercredi | B18: J1 | C18: MC | E18: TE | G18: TE | I18: MC | K18: MC | M18: TE | Q18: MC
B19: J2 | C19: TE | D19: AS | E19: AS | F19: CB | G19: CB | H19: AS | I19: XB | L19: AS | M19: IEG | N19: AS | O19: CB | P19: CC | Q19: XB
B20: J3 | C20: IEG | E20: XB | G20: CC | J20: CB | K20: TE | M20: XB | N20: CB | P20: TE | Q20: IEG | R20: AS
B21: J4 | J21: AS | P21: AS
B22: J6
B23: J7
B24: J8
A25: Jeudi | B25: J1 | C25: TE | E25: CC | G25: CC | I25: MY | M25: IEG | O25: CC
B26: J2 | C26: LD | D26: XB | E26: CB | F26: TE | G26: LD | H26: XB | I26: IEG | J26: TE | K26: XB | L26: MY | M26: AS | N26: CB | O26: MY | P26: XB | Q26: IEG | R26: TE
B27: J3 | C27: MY | D27: CC | E27: IEG | F27: XB | G27: IEG | H27: TE | I27: XB | J27: CC | K27: TE | L27: LD | M27: XB | N27: TE | O27: TE | P27: LD | Q27: XB | R27: CB
B28: J4 | C28: IEG | D28: CB | F28: MY | H28: MY | J28: CB | K28: IEG | L28: CB | N28: CC | R28: CC
B29: J6
B30: J7 | F30: LD | L30: CC | N30: MY
B31: J8
A32: vendredi | B32: J1 | C32: XB | E32: XB | G32: LD | I32: AS | K32: XB | M32: LD | Q32: AS
B33: J2 | C33: IEG | D33: MY | E33: CC | F33: MC | G33: MY | H33: MC | I33: TE | J33: CB | K33: MY | L33: LD | M33: MC | N33: CC | P33: LD | Q33: LD
B34: J3 | C34: MC | E34: MY | F34: AS | I34: MC | J34: LD | L34: MC | M34: IEG | N34: MY | O34: MC | P34: MY | Q34: TE | R34: CB
B35: J4 | E35: IEG | G35: IEG | N35: AS | R35: MC
B36: J6
B37: J7 | N37: XB | R37: MY
B38: J8
A39: Samedi | B39: Garde | C39: CB | D39: AS | E39: CC | F39: MC | G39: XB | H39: TE | I39: IEG | J39: MY | K39: AS | L39: CB | M39: MC | N39: CC | O39: TE | P39: XB | Q39: MY
B40: Doublon | E40: LD | K40: IEG | N40: LD | Q40: IEG
A41: Dimanche | B41: Garde | C41: CB | D41: AS | E41: CC | F41: MC | G41: XB | H41: TE | I41: IEG | J41: MY | K41: AS | L41: CB | M41: MC | N41: CC | O41: TE | P41: XB | Q41: MY
...

Sheet Matthieu Cadennes
A1: Planning V2 — Matthieu Cadennes (MC)
A2: Roulement sur 8 semaines · lié à la feuille "Roulement V2" (mise à jour automatique)
A4: Jour | B4: S1 | C4: S2 | D4: S3 | E4: S4 | F4: S5 | G4: S6 | H4: S7 | I4: S8
A5: Lundi
A6: Mardi
A7: Mercredi
A8: Jeudi
A9: vendredi
A10: Samedi | B10: {=_xlfn.TEXTJOIN(" + ",TRUE,IF('Roulement V2'!C39="MC","Garde · Beaune",""),IF('Roulement V2'!D39="MC","Garde · Dijon",""),IF('Roulement V2'!C40="MC","Doublon · Beaune",""),IF('Roulement V2'!D40="MC","Doublon · Dijon",""))} | C10: {=_xlfn.TEXTJOIN(" + ",TRUE,IF('Roulement V2'!E39="MC","Garde · Beaune",""),IF('Roulement V2'!F39="MC","Garde · Dijon",""),IF('Roulement V2'!E40="MC","Doublon · Beaune",""),IF('Roulement V2'!F40="MC","Doublon · Dijon",""))} -> Garde · Dijon | D10: {=_xlfn.TEXTJOIN(" + ",TRUE,IF('Roulement V2'!G39="MC","Garde · Beaune",""),IF('Roulement V2'!H39="MC","Garde · Dijon",""),IF('Roulement V2'!G40="MC","Doublon · Beaune",""),IF('Roulement V2'!H40="MC","Doublon · Dijon",""))} | E10: {=_xlfn.TEXTJOIN(" + ",TRUE,IF('Roulement V2'!I39="MC","Garde · Beaune",""),IF('Roulement V2'!J39="MC","Garde · Dijon",""),IF('Roulement V2'!I40="MC","Doublon · Beaune",""),IF('Roulement V2'!J40="MC","Doublon · Dijon",""))} | F10: {=_xlfn.TEXTJOIN(" + ",TRUE,IF('Roulement V2'!K39="MC","Garde · Beaune",""),IF('Roulement V2'!L39="MC","Garde · Dijon",""),IF('Roulement V2'!K40="MC","Doublon · Beaune",""),IF('Roulement V2'!L40="MC","Doublon · Dijon",""))} | G10: {=_xlfn.TEXTJOIN(" + ",TRUE,IF('Roulement V2'!M39="MC","Garde · Beaune",""),IF('Roulement V2'!N39="MC","Garde · Dijon",""),IF('Roulement V2'!M40="MC","Doublon · Beaune",""),IF('Roulement V2'!N40="MC","Doublon · Dijon",""))} -> Garde · Beaune | H10: {=_xlfn.TEXTJOIN(" + ",TRUE,IF('Roulement V2'!O39="MC","Garde · Beaune",""),IF('Roulement V2'!P39="MC","Garde · Dijon",""),IF('Roulement V2'!O40="MC","Doublon · Beaune",""),IF('Roulement V2'!P40="MC","Doublon · Dijon",""))} | I10: {=_xlfn.TEXTJOIN(" + ",TRUE,IF('Roulement V2'!Q39="MC","Garde · Beaune",""),IF('Roulement V2'!R39="MC","Garde · Dijon",""),IF('Roulement V2'!Q40="MC","Doublon · Beaune",""),IF('Roulement V2'!R40="MC","Doublon · Dijon",""))}
A11: Dimanche | B11: {=_xlfn.TEXTJOIN(" + ",TRUE,IF('Roulement V2'!C41="MC","Garde · Beaune",""),IF('Roulement V2'!D41="MC","Garde · Dijon",""),IF('Roulement V2'!C42="MC","Doublon · Beaune",""),IF('Roulement V2'!D42="MC","Doublon · Dijon",""))} | C11: {=_xlfn.TEXTJOIN(" + ",TRUE,IF('Roulement V2'!E41="MC","Garde · Beaune",""),IF('Roulement V2'!F41="MC","Garde · Dijon",""),IF('Roulement V2'!E42="MC","Doublon · Beaune",""),IF('Roulement V2'!F42="MC","Doublon · Dijon",""))} -> Garde · Dijon | D11: {=_xlfn.TEXTJOIN(" + ",TRUE,IF('Roulement V2'!G41="MC","Garde · Beaune",""),IF('Roulement V2'!H41="MC","Garde · Dijon",""),IF('Roulement V2'!G42="MC","Doublon · Beaune",""),IF('Roulement V2'!H42="MC","Doublon · Dijon",""))} | E11: {=_xlfn.TEXTJOIN(" + ",TRUE,IF('Roulement V2'!I41="MC","Garde · Beaune",""),IF('Roulement V2'!J41="MC","Garde · Dijon",""),IF('Roulement V2'!I42="MC","Doublon · Beaune",""),IF('Roulement V2'!J42="MC","Doublon · Dijon",""))} | F11: {=_xlfn.TEXTJOIN(" + ",TRUE,IF('Roulement V2'!K41="MC","Garde · Beaune",""),IF('Roulement V2'!L41="MC","Garde · Dijon",""),IF('Roulement V2'!K42="MC","Doublon · Beaune",""),IF('Roulement V2'!L42="MC","Doublon · Dijon",""))} | G11: {=_xlfn.TEXTJOIN(" + ",TRUE,IF('Roulement V2'!M41="MC","Garde · Beaune",""),IF('Roulement V2'!N41="MC","Garde · Dijon",""),IF('Roulement V2'!M42="MC","Doublon · Beaune",""),IF('Roulement V2'!N42="MC","Doublon · Dijon",""))} -> Garde · Beaune | H11: {=_xlfn.TEXTJOIN(" + ",TRUE,IF('Roulement V2'!O41="MC","Garde · Beaune",""),IF('Roulement V2'!P41="MC","Garde · Dijon",""),IF('Roulement V2'!O42="MC","Doublon · Beaune",""),IF('Roulement V2'!P42="MC","Doublon · Dijon",""))} | I11: {=_xlfn.TEXTJOIN(" + ",TRUE,IF('Roulement V2'!Q41="MC","Garde · Beaune",""),IF('Roulement V2'!R41="MC","Garde · Dijon",""),IF('Roulement V2'!Q42="MC","Doublon · Beaune",""),IF('Roulement V2'!R42="MC","Doublon · Dijon",""))}
A14: Récapitulatif — sur 8 semaines (mise à jour automatique)
A15: J1 · 8h-16h | B15: {=COUNTIF(B5:I9,"*J1 · 8h-16h*")} -> 0 | D15: Beaune | E15: {=COUNTIF(B5:I9,"*Beaune*")} -> 0
A16: J2 · 14h-22h | B16: {=COUNTIF(B5:I9,"*J2 · 14h-22h*")} -> 0 | D16: Dijon | E16: {=COUNTIF(B5:I9,"*Dijon*")} -> 0
A17: Journée · 8h-18h30 | B17: {=COUNTIF(B5:I9,"*journée · 8h-18h30*")} -> 0
A18: Total semaine | B18: {=COUNTIF(B5:I9,"?*")} -> 0 | D18: Gardes WE | E18: {=COUNTIF(B10:I11,"*Garde*")} -> 4
D19: Doublons WE | E19: {=COUNTIF(B10:I11,"*Doublon*")} -> 0

Sheet Caroline Chauvet
A1: Planning V2 — Caroline Chauvet (CC)
A2: Roulement sur 8 semaines · lié à la feuille "Roulement V2" (mise à jour automatique)
A4: Jour | B4: S1 | C4: S2 | D4: S3 | E4: S4 | F4: S5 | G4: S6 | H4: S7 | I4: S8
A5: Lundi
A6: Mardi
A7: Mercredi
A8: Jeudi
A9: vendredi
A10: Samedi | B10: {=_xlfn.TEXTJOIN(" + ",TRUE,IF('Roulement V2'!C39="CC","Garde · Beaune",""),IF('Roulement V2'!D39="CC","Garde · Dijon",""),IF('Roulement V2'!C40="CC","Doublon · Beaune",""),IF('Roulement V2'!D40="CC","Doublon · Dijon",""))} | C10: {=_xlfn.TEXTJOIN(" + ",TRUE,IF('Roulement V2'!E39="CC","Garde · Beaune",""),IF('Roulement V2'!F39="CC","Garde · Dijon",""),IF('Roulement V2'!E40="CC","Doublon · Beaune",""),IF('Roulement V2'!F40="CC","Doublon · Dijon",""))} -> Garde · Beaune | D10: {=_xlfn.TEXTJOIN(" + ",TRUE,IF('Roulement V2'!G39="CC","Garde · Beaune",""),IF('Roulement V2'!H39="CC","Garde · Dijon",""),IF('Roulement V2'!G40="CC","Doublon · Beaune",""),IF('Roulement V2'!H40="CC","Doublon · Dijon",""))} | E10: {=_xlfn.TEXTJOIN(" + ",TRUE,IF('Roulement V2'!I39="CC","Garde · Beaune",""),IF('Roulement V2'!J39="CC","Garde · Dijon",""),IF('Roulement V2'!I40="CC","Doublon · Beaune",""),IF('Roulement V2'!J40="CC","Doublon · Dijon",""))} | F10: {=_xlfn.TEXTJOIN(" + ",TRUE,IF('Roulement V2'!K39="CC","Garde · Beaune",""),IF('Roulement V2'!L39="CC","Garde · Dijon",""),IF('Roulement V2'!K40="CC","Doublon · Beaune",""),IF('Roulement V2'!L40="CC","Doublon · Dijon",""))} | G10: {=_xlfn.TEXTJOIN(" + ",TRUE,IF('Roulement V2'!M39="CC","Garde · Beaune",""),IF('Roulement V2'!N39="CC","Garde · Dijon",""),IF('Roulement V2'!M40="CC","Doublon · Beaune",""),IF('Roulement V2'!N40="CC","Doublon · Dijon",""))} -> Garde · Dijon | H10: {=_xlfn.TEXTJOIN(" + ",TRUE,IF('Roulement V2'!O39="CC","Garde · Beaune",""),IF('Roulement V2'!P39="CC","Garde · Dijon",""),IF('Roulement V2'!O40="CC","Doublon · Beaune",""),IF('Roulement V2'!P40="CC","Doublon · Dijon",""))} | I10: {=_xlfn.TEXTJOIN(" + ",TRUE,IF('Roulement V2'!Q39="CC","Garde · Beaune",""),IF('Roulement V2'!R39="CC","Garde · Dijon",""),IF('Roulement V2'!Q40="CC","Doublon · Beaune",""),IF('Roulement V2'!R40="CC","Doublon · Dijon",""))}
A11: Dimanche | B11: {=_xlfn.TEXTJOIN(" + ",TRUE,IF('Roulement V2'!C41="CC","Garde · Beaune",""),IF('Roulement V2'!D41="CC","Garde · Dijon",""),IF('Roulement V2'!C42="CC","Doublon · Beaune",""),IF('Roulement V2'!D42="CC","Doublon · Dijon",""))} | C11: {=_xlfn.TEXTJOIN(" + ",TRUE,IF('Roulement V2'!E41="CC","Garde · Beaune",""),IF('Roulement V2'!F41="CC","Garde · Dijon",""),IF('Roulement V2'!E42="CC","Doublon · Beaune",""),IF('Roulement V2'!F42="CC","Doublon · Dijon",""))} -> Garde · Beaune | D11: {=_xlfn.TEXTJOIN(" + ",TRUE,IF('Roulement V2'!G41="CC","Garde · Beaune",""),IF('Roulement V2'!H41="CC","Garde · Dijon",""),IF('Roulement V2'!G42="CC","Doublon · Beaune",""),IF('Roulement V2'!H42="CC","Doublon · Dijon",""))} | E11: {=_xlfn.TEXTJOIN(" + ",TRUE,IF('Roulement V2'!I41="CC","Garde · Beaune",""),IF('Roulement V2'!J41="CC","Garde · Dijon",""),IF('Roulement V2'!I42="CC","Doublon · Beaune",""),IF('Roulement V2'!J42="CC","Doublon · Dijon",""))} | F11: {=_xlfn.TEXTJOIN(" + ",TRUE,IF('Roulement V2'!K41="CC","Garde · Beaune",""),IF('Roulement V2'!L41="CC","Garde · Dijon",""),IF('Roulement V2'!K42="CC","Doublon · Beaune",""),IF('Roulement V2'!L42="CC","Doublon · Dijon",""))} | G11: {=_xlfn.TEXTJOIN(" + ",TRUE,IF('Roulement V2'!M41="CC","Garde · Beaune",""),IF('Roulement V2'!N41="CC","Garde · Dijon",""),IF('Roulement V2'!M42="CC","Doublon · Beaune",""),IF('Roulement V2'!N42="CC","Doublon · Dijon",""))} -> Garde · Dijon | H11: {=_xlfn.TEXTJOIN(" + ",TRUE,IF('Roulement V2'!O41="CC","Garde · Beaune",""),IF('Roulement V2'!P41="CC","Garde · Dijon",""),IF('Roulement V2'!O42="CC","Doublon · Beaune",""),IF('Roulement V2'!P42="CC","Doublon · Dijon",""))} | I11: {=_xlfn.TEXTJOIN(" + ",TRUE,IF('Roulement V2'!Q41="CC","Garde · Beaune",""),IF('Roulement V2'!R41="CC","Garde · Dijon",""),IF('Roulement V2'!Q42="CC","Doublon · Beaune",""),IF('Roulement V2'!R42="CC","Doublon · Dijon",""))}
A14: Récapitulatif — sur 8 semaines (mise à jour automatique)
A15: J1 · 8h-16h | B15: {=COUNTIF(B5:I9,"*J1 · 8h-16h*")} -> 0 | D15: Beaune | E15: {=COUNTIF(B5:I9,"*Beaune*")} -> 0
A16: J2 · 14h-22h | B16: {=COUNTIF(B5:I9,"*J2 · 14h-22h*")} -> 0 | D16: Dijon | E16: {=COUNTIF(B5:I9,"*Dijon*")} -> 0
A17: Journée · 8h-18h30 | B17: {=COUNTIF(B5:I9,"*journée · 8h-18h30*")} -> 0
A18: Total semaine | B18: {=COUNTIF(B5:I9,"?*")} -> 0 | D18: Gardes WE | E18: {=COUNTIF(B10:I11,"*Garde*")} -> 4
D19: Doublons WE | E19: {=COUNTIF(B10:I11,"*Doublon*")} -> 0

Sheet Xavier Baudrillart
A1: Planning V2 — Xavier Baudrillart (XB)
A2: Roulement sur 8 semaines · lié à la feuille "Roulement V2" (mise à jour automatique)
A4: Jour | B4: S1 | C4: S2 | D4: S3 | E4: S4 | F4: S5 | G4: S6 | H4: S7 | I4: S8
A5: Lundi
A6: Mardi
A7: Mercredi
A8: Jeudi
A9: vendredi
A10: Samedi | B10: {=_xlfn.TEXTJOIN(" + ",TRUE,IF('Roulement V2'!C39="XB","Garde · Beaune",""),IF('Roulement V2'!D39="XB","Garde · Dijon",""),IF('Roulement V2'!C40="XB","Doublon · Beaune",""),IF('Roulement V2'!D40="XB","Doublon · Dijon",""))} | C10: {=_xlfn.TEXTJOIN(" + ",TRUE,IF('Roulement V2'!E39="XB","Garde · Beaune",""),IF('Roulement V2'!F39="XB","Garde · Dijon",""),IF('Roulement V2'!E40="XB","Doublon · Beaune",""),IF('Roulement V2'!F40="XB","Doublon · Dijon",""))} | D10: {=_xlfn.TEXTJOIN(" + ",TRUE,IF('Roulement V2'!G39="XB","Garde · Beaune",""),IF('Roulement V2'!H39="XB","Garde · Dijon",""),IF('Roulement V2'!G40="XB","Doublon · Beaune",""),IF('Roulement V2'!H40="XB","Doublon · Dijon",""))} -> Garde · Beaune | E10: {=_xlfn.TEXTJOIN(" + ",TRUE,IF('Roulement V2'!I39="XB","Garde · Beaune",""),IF('Roulement V2'!J39="XB","Garde · Dijon",""),IF('Roulement V2'!I40="XB","Doublon · Beaune",""),IF('Roulement V2'!J40="XB","Doublon · Dijon",""))} | F10: {=_xlfn.TEXTJOIN(" + ",TRUE,IF('Roulement V2'!K39="XB","Garde · Beaune",""),IF('Roulement V2'!L39="XB","Garde · Dijon",""),IF('Roulement V2'!K40="XB","Doublon · Beaune",""),IF('Roulement V2'!L40="XB","Doublon · Dijon",""))} | G10: {=_xlfn.TEXTJOIN(" + ",TRUE,IF('Roulement V2'!M39="XB","Garde · Beaune",""),IF('Roulement V2'!N39="XB","Garde · Dijon",""),IF('Roulement V2'!M40="XB","Doublon · Beaune",""),IF('Roulement V2'!N40="XB","Doublon · Dijon",""))} | H10: {=_xlfn.TEXTJOIN(" + ",TRUE,IF('Roulement V2'!O39="XB","Garde · Beaune",""),IF('Roulement V2'!P39="XB","Garde · Dijon",""),IF('Roulement V2'!O40="XB","Doublon · Beaune",""),IF('Roulement V2'!P40="XB","Doublon · Dijon",""))} -> Garde · Dijon | I10: {=_xlfn.TEXTJOIN(" + ",TRUE,IF('Roulement V2'!Q39="XB","Garde · Beaune",""),IF('Roulement V2'!R39="XB","Garde · Dijon",""),IF('Roulement V2'!Q40="XB","Doublon · Beaune",""),IF('Roulement V2'!R40="XB","Doublon · Dijon",""))}
A11: Dimanche | B11: {=_xlfn.TEXTJOIN(" + ",TRUE,IF('Roulement V2'!C41="XB","Garde · Beaune",""),IF('Roulement V2'!D41="XB","Garde · Dijon",""),IF('Roulement V2'!C42="XB","Doublon · Beaune",""),IF('Roulement V2'!D42="XB","Doublon · Dijon",""))} | C11: {=_xlfn.TEXTJOIN(" + ",TRUE,IF('Roulement V2'!E41="XB","Garde · Beaune",""),IF('Roulement V2'!F41="XB","Garde · Dijon",""),IF('Roulement V2'!E42="XB","Doublon · Beaune",""),IF('Roulement V2'!F42="XB","Doublon · Dijon",""))} | D11: {=_xlfn.TEXTJOIN(" + ",TRUE,IF('Roulement V2'!G41="XB","Garde · Beaune",""),IF('Roulement V2'!H41="XB","Garde · Dijon",""),IF('Roulement V2'!G42="XB","Doublon · Beaune",""),IF('Roulement V2'!H42="XB","Doublon · Dijon",""))} -> Garde · Beaune | E11: {=_xlfn.TEXTJOIN(" + ",TRUE,IF('Roulement V2'!I41="XB","Garde · Beaune",""),IF('Roulement V2'!J41="XB","Garde · Dijon",""),IF('Roulement V2'!I42="XB","Doublon · Beaune",""),IF('Roulement V2'!J42="XB","Doublon · Dijon",""))} | F11: {=_xlfn.TEXTJOIN(" + ",TRUE,IF('Roulement V2'!K41="XB","Garde · Beaune",""),IF('Roulement V2'!L41="XB","Garde · Dijon",""),IF('Roulement V2'!K42="XB","Doublon · Beaune",""),IF('Roulement V2'!L42="XB","Doublon · Dijon",""))} | G11: {=_xlfn.TEXTJOIN(" + ",TRUE,IF('Roulement V2'!M41="XB","Garde · Beaune",""),IF('Roulement V2'!N41="XB","Garde · Dijon",""),IF('Roulement V2'!M42="XB","Doublon · Beaune",""),IF('Roulement V2'!N42="XB","Doublon · Dijon",""))} | H11: {=_xlfn.TEXTJOIN(" + ",TRUE,IF('Roulement V2'!O41="XB","Garde · Beaune",""),IF('Roulement V2'!P41="XB","Garde · Dijon",""),IF('Roulement V2'!O42="XB","Doublon · Beaune",""),IF('Roulement V2'!P42="XB","Doublon · Dijon",""))} -> Garde · Dijon | I11: {=_xlfn.TEXTJOIN(" + ",TRUE,IF('Roulement V2'!Q41="XB","Garde · Beaune",""),IF('Roulement V2'!R41="XB","Garde · Dijon",""),IF('Roulement V2'!Q42="XB","Doublon · Beaune",""),IF('Roulement V2'!R42="XB","Doublon · Dijon",""))}
A14: Récapitulatif — sur 8 semaines (mise à jour automatique)
A15: J1 · 8h-16h | B15: {=COUNTIF(B5:I9,"*J1 · 8h-16h*")} -> 0 | D15: Beaune | E15: {=COUNTIF(B5:I9,"*Beaune*")} -> 0
A16: J2 · 14h-22h | B16: {=COUNTIF(B5:I9,"*J2 · 14h-22h*")} -> 0 | D16: Dijon | E16: {=COUNTIF(B5:I9,"*Dijon*")} -> 0
A17: Journée · 8h-18h30 | B17: {=COUNTIF(B5:I9,"*journée · 8h-18h30*")} -> 0
A18: Total semaine | B18: {=COUNTIF(B5:I9,"?*")} -> 0 | D18: Gardes WE | E18: {=COUNTIF(B10:I11,"*Garde*")} -> 4
D19: Doublons WE | E19: {=COUNTIF(B10:I11,"*Doublon*")} -> 0

Sheet Thomas Etienne
A1: Planning V2 — Thomas Etienne (TE)
A2: Roulement sur 8 semaines · lié à la feuille "Roulement V2" (mise à jour automatique)
A4: Jour | B4: S1 | C4: S2 | D4: S3 | E4: S4 | F4: S5 | G4: S6 | H4: S7 | I4: S8
A5: Lundi
A6: Mardi
A7: Mercredi
A8: Jeudi
A9: vendredi
A10: Samedi | B10: {=_xlfn.TEXTJOIN(" + ",TRUE,IF('Roulement V2'!C39="TE","Garde · Beaune",""),IF('Roulement V2'!D39="TE","Garde · Dijon",""),IF('Roulement V2'!C40="TE","Doublon · Beaune",""),IF('Roulement V2'!D40="TE","Doublon · Dijon",""))} | C10: {=_xlfn.TEXTJOIN(" + ",TRUE,IF('Roulement V2'!E39="TE","Garde · Beaune",""),IF('Roulement V2'!F39="TE","Garde · Dijon",""),IF('Roulement V2'!E40="TE","Doublon · Beaune",""),IF('Roulement V2'!F40="TE","Doublon · Dijon",""))} | D10: {=_xlfn.TEXTJOIN(" + ",TRUE,IF('Roulement V2'!G39="TE","Garde · Beaune",""),IF('Roulement V2'!H39="TE","Garde · Dijon",""),IF('Roulement V2'!G40="TE","Doublon · Beaune",""),IF('Roulement V2'!H40="TE","Doublon · Dijon",""))} -> Garde · Dijon | E10: {=_xlfn.TEXTJOIN(" + ",TRUE,IF('Roulement V2'!I39="TE","Garde · Beaune",""),IF('Roulement V2'!J39="TE","Garde · Dijon",""),IF('Roulement V2'!I40="TE","Doublon · Beaune",""),IF('Roulement V2'!J40="TE","Doublon · Dijon",""))} | F10: {=_xlfn.TEXTJOIN(" + ",TRUE,IF('Roulement V2'!K39="TE","Garde · Beaune",""),IF('Roulement V2'!L39="TE","Garde · Dijon",""),IF('Roulement V2'!K40="TE","Doublon · Beaune",""),IF('Roulement V2'!L40="TE","Doublon · Dijon",""))} | G10: {=_xlfn.TEXTJOIN(" + ",TRUE,IF('Roulement V2'!M39="TE","Garde · Beaune",""),IF('Roulement V2'!N39="TE","Garde · Dijon",""),IF('Roulement V2'!M40="TE","Doublon · Beaune",""),IF('Roulement V2'!N40="TE","Doublon · Dijon",""))} | H10: {=_xlfn.TEXTJOIN(" + ",TRUE,IF('Roulement V2'!O39="TE","Garde · Beaune",""),IF('Roulement V2'!P39="TE","Garde · Dijon",""),IF('Roulement V2'!O40="TE","Doublon · Beaune",""),IF('Roulement V2'!P40="TE","Doublon · Dijon",""))} -> Garde · Beaune | I10: {=_xlfn.TEXTJOIN(" + ",TRUE,IF('Roulement V2'!Q39="TE","Garde · Beaune",""),IF('Roulement V2'!R39="TE","Garde · Dijon",""),IF('Roulement V2'!Q40="TE","Doublon · Beaune",""),IF('Roulement V2'!R40="TE","Doublon · Dijon",""))}
A11: Dimanche | B11: {=_xlfn.TEXTJOIN(" + ",TRUE,IF('Roulement V2'!C41="TE","Garde · Beaune",""),IF('Roulement V2'!D41="TE","Garde · Dijon",""),IF('Roulement V2'!C42="TE","Doublon · Beaune",""),IF('Roulement V2'!D42="TE","Doublon · Dijon",""))} | C11: {=_xlfn.TEXTJOIN(" + ",TRUE,IF('Roulement V2'!E41="TE","Garde · Beaune",""),IF('Roulement V2'!F41="TE","Garde · Dijon",""),IF('Roulement V2'!E42="TE","Doublon · Beaune",""),IF('Roulement V2'!F42="TE","Doublon · Dijon",""))} | D11: {=_xlfn.TEXTJOIN(" + ",TRUE,IF('Roulement V2'!G41="TE","Garde · Beaune",""),IF('Roulement V2'!H41="TE","Garde · Dijon",""),IF('Roulement V2'!G42="TE","Doublon · Beaune",""),IF('Roulement V2'!H42="TE","Doublon · Dijon",""))} -> Garde · Dijon | E11: {=_xlfn.TEXTJOIN(" + ",TRUE,IF('Roulement V2'!I41="TE","Garde · Beaune",""),IF('Roulement V2'!J41="TE","Garde · Dijon",""),IF('Roulement V2'!I42="TE","Doublon · Beaune",""),IF('Roulement V2'!J42="TE","Doublon · Dijon",""))} | F11: {=_xlfn.TEXTJOIN(" + ",TRUE,IF('Roulement V2'!K41="TE","Garde · Beaune",""),IF('Roulement V2'!L41="TE","Garde · Dijon",""),IF('Roulement V2'!K42="TE","Doublon · Beaune",""),IF('Roulement V2'!L42="TE","Doublon · Dijon",""))} | G11: {=_xlfn.TEXTJOIN(" + ",TRUE,IF('Roulement V2'!M41="TE","Garde · Beaune",""),IF('Roulement V2'!N41="TE","Garde · Dijon",""),IF('Roulement V2'!M42="TE","Doublon · Beaune",""),IF('Roulement V2'!N42="TE","Doublon · Dijon",""))} | H11: {=_xlfn.TEXTJOIN(" + ",TRUE,IF('Roulement V2'!O41="TE","Garde · Beaune",""),IF('Roulement V2'!P41="TE","Garde · Dijon",""),IF('Roulement V2'!O42="TE","Doublon · Beaune",""),IF('Roulement V2'!P42="TE","Doublon · Dijon",""))} -> Garde · Beaune | I11: {=_xlfn.TEXTJOIN(" + ",TRUE,IF('Roulement V2'!Q41="TE","Garde · Beaune",""),IF('Roulement V2'!R41="TE","Garde · Dijon",""),IF('Roulement V2'!Q42="TE","Doublon · Beaune",""),IF('Roulement V2'!R42="TE","Doublon · Dijon",""))}
A14: Récapitulatif — sur 8 semaines (mise à jour automatique)
A15: J1 · 8h-16h | B15: {=COUNTIF(B5:I9,"*J1 · 8h-16h*")} -> 0 | D15: Beaune | E15: {=COUNTIF(B5:I9,"*Beaune*")} -> 0
A16: J2 · 14h-22h | B16: {=COUNTIF(B5:I9,"*J2 · 14h-22h*")} -> 0 | D16: Dijon | E16: {=COUNTIF(B5:I9,"*Dijon*")} -> 0
A17: Journée · 8h-18h30 | B17: {=COUNTIF(B5:I9,"*journée · 8h-18h30*")} -> 0
A18: Total semaine | B18: {=COUNTIF(B5:I9,"?*")} -> 0 | D18: Gardes WE | E18: {=COUNTIF(B10:I11,"*Garde*")} -> 4
D19: Doublons WE | E19: {=COUNTIF(B10:I11,"*Doublon*")} -> 0

Sheet Airelle Sauvage
A1: Planning V2 — Airelle Sauvage (AS)
A2: Roulement sur 8 semaines · lié à la feuille "Roulement V2" (mise à jour automatique)
A4: Jour | B4: S1 | C4: S2 | D4: S3 | E4: S4 | F4: S5 | G4: S6 | H4: S7 | I4: S8
A5: Lundi
A6: Mardi
A7: Mercredi
A8: Jeudi
A9: vendredi
A10: Samedi | B10: {=_xlfn.TEXTJOIN(" + ",TRUE,IF('Roulement V2'!C39="AS","Garde · Beaune",""),IF('Roulement V2'!D39="AS","Garde · Dijon",""),IF('Roulement V2'!C40="AS","Doublon · Beaune",""),IF('Roulement V2'!D40="AS","Doublon · Dijon",""))} -> Garde · Dijon | C10: {=_xlfn.TEXTJOIN(" + ",TRUE,IF('Roulement V2'!E39="AS","Garde · Beaune",""),IF('Roulement V2'!F39="AS","Garde · Dijon",""),IF('Roulement V2'!E40="AS","Doublon · Beaune",""),IF('Roulement V2'!F40="AS","Doublon · Dijon",""))} | D10: {=_xlfn.TEXTJOIN(" + ",TRUE,IF('Roulement V2'!G39="AS","Garde · Beaune",""),IF('Roulement V2'!H39="AS","Garde · Dijon",""),IF('Roulement V2'!G40="AS","Doublon · Beaune",""),IF('Roulement V2'!H40="AS","Doublon · Dijon",""))} | E10: {=_xlfn.TEXTJOIN(" + ",TRUE,IF('Roulement V2'!I39="AS","Garde · Beaune",""),IF('Roulement V2'!J39="AS","Garde · Dijon",""),IF('Roulement V2'!I40="AS","Doublon · Beaune",""),IF('Roulement V2'!J40="AS","Doublon · Dijon",""))} | F10: {=_xlfn.TEXTJOIN(" + ",TRUE,IF('Roulement V2'!K39="AS","Garde · Beaune",""),IF('Roulement V2'!L39="AS","Garde · Dijon",""),IF('Roulement V2'!K40="AS","Doublon · Beaune",""),IF('Roulement V2'!L40="AS","Doublon · Dijon",""))} -> Garde · Beaune | G10: {=_xlfn.TEXTJOIN(" + ",TRUE,IF('Roulement V2'!M39="AS","Garde · Beaune",""),IF('Roulement V2'!N39="AS","Garde · Dijon",""),IF('Roulement V2'!M40="AS","Doublon · Beaune",""),IF('Roulement V2'!N40="AS","Doublon · Dijon",""))} | H10: {=_xlfn.TEXTJOIN(" + ",TRUE,IF('Roulement V2'!O39="AS","Garde · Beaune",""),IF('Roulement V2'!P39="AS","Garde · Dijon",""),IF('Roulement V2'!O40="AS","Doublon · Beaune",""),IF('Roulement V2'!P40="AS","Doublon · Dijon",""))} | I10: {=_xlfn.TEXTJOIN(" + ",TRUE,IF('Roulement V2'!Q39="AS","Garde · Beaune",""),IF('Roulement V2'!R39="AS","Garde · Dijon",""),IF('Roulement V2'!Q40="AS","Doublon · Beaune",""),IF('Roulement V2'!R40="AS","Doublon · Dijon",""))}
A11: Dimanche | B11: {=_xlfn.TEXTJOIN(" + ",TRUE,IF('Roulement V2'!C41="AS","Garde · Beaune",""),IF('Roulement V2'!D41="AS","Garde · Dijon",""),IF('Roulement V2'!C42="AS","Doublon · Beaune",""),IF('Roulement V2'!D42="AS","Doublon · Dijon",""))} -> Garde · Dijon | C11: {=_xlfn.TEXTJOIN(" + ",TRUE,IF('Roulement V2'!E41="AS","Garde · Beaune",""),IF('Roulement V2'!F41="AS","Garde · Dijon",""),IF('Roulement V2'!E42="AS","Doublon · Beaune",""),IF('Roulement V2'!F42="AS","Doublon · Dijon",""))} | D11: {=_xlfn.TEXTJOIN(" + ",TRUE,IF('Roulement V2'!G41="AS","Garde · Beaune",""),IF('Roulement V2'!H41="AS","Garde · Dijon",""),IF('Roulement V2'!G42="AS","Doublon · Beaune",""),IF('Roulement V2'!H42="AS","Doublon · Dijon",""))} | E11: {=_xlfn.TEXTJOIN(" + ",TRUE,IF('Roulement V2'!I41="AS","Garde · Beaune",""),IF('Roulement V2'!J41="AS","Garde · Dijon",""),IF('Roulement V2'!I42="AS","Doublon · Beaune",""),IF('Roulement V2'!J42="AS","Doublon · Dijon",""))} | F11: {=_xlfn.TEXTJOIN(" + ",TRUE,IF('Roulement V2'!K41="AS","Garde · Beaune",""),IF('Roulement V2'!L41="AS","Garde · Dijon",""),IF('Roulement V2'!K42="AS","Doublon · Beaune",""),IF('Roulement V2'!L42="AS","Doublon · Dijon",""))} -> Garde · Beaune | G11: {=_xlfn.TEXTJOIN(" + ",TRUE,IF('Roulement V2'!M41="AS","Garde · Beaune",""),IF('Roulement V2'!N41="AS","Garde · Dijon",""),IF('Roulement V2'!M42="AS","Doublon · Beaune",""),IF('Roulement V2'!N42="AS","Doublon · Dijon",""))} | H11: {=_xlfn.TEXTJOIN(" + ",TRUE,IF('Roulement V2'!O41="AS","Garde · Beaune",""),IF('Roulement V2'!P41="AS","Garde · Dijon",""),IF('Roulement V2'!O42="AS","Doublon · Beaune",""),IF('Roulement V2'!P42="AS","Doublon · Dijon",""))} | I11: {=_xlfn.TEXTJOIN(" + ",TRUE,IF('Roulement V2'!Q41="AS","Garde · Beaune",""),IF('Roulement V2'!R41="AS","Garde · Dijon",""),IF('Roulement V2'!Q42="AS","Doublon · Beaune",""),IF('Roulement V2'!R42="AS","Doublon · Dijon",""))}
A14: Récapitulatif — sur 8 semaines (mise à jour automatique)
A15: J1 · 8h-16h | B15: {=COUNTIF(B5:I9,"*J1 · 8h-16h*")} -> 0 | D15: Beaune | E15: {=COUNTIF(B5:I9,"*Beaune*")} -> 0
A16: J2 · 14h-22h | B16: {=COUNTIF(B5:I9,"*J2 · 14h-22h*")} -> 0 | D16: Dijon | E16: {=COUNTIF(B5:I9,"*Dijon*")} -> 0
A17: Journée · 8h-18h30 | B17: {=COUNTIF(B5:I9,"*journée · 8h-18h30*")} -> 0
A18: Total semaine | B18: {=COUNTIF(B5:I9,"?*")} -> 0 | D18: Gardes WE | E18: {=COUNTIF(B10:I11,"*Garde*")} -> 4
D19: Doublons WE | E19: {=COUNTIF(B10:I11,"*Doublon*")} -> 0

Sheet Christophe Bertrand
A1: Planning V2 — Christophe Bertrand (CB)
A2: Roulement sur 8 semaines · lié à la feuille "Roulement V2" (mise à jour automatique)
A4: Jour | B4: S1 | C4: S2 | D4: S3 | E4: S4 | F4: S5 | G4: S6 | H4: S7 | I4: S8
A5: Lundi
A6: Mardi
A7: Mercredi
A8: Jeudi
A9: vendredi
A10: Samedi | B10: {=_xlfn.TEXTJOIN(" + ",TRUE,IF('Roulement V2'!C39="CB","Garde · Beaune",""),IF('Roulement V2'!D39="CB","Garde · Dijon",""),IF('Roulement V2'!C40="CB","Doublon · Beaune",""),IF('Roulement V2'!D40="CB","Doublon · Dijon",""))} -> Garde · Beaune | C10: {=_xlfn.TEXTJOIN(" + ",TRUE,IF('Roulement V2'!E39="CB","Garde · Beaune",""),IF('Roulement V2'!F39="CB","Garde · Dijon",""),IF('Roulement V2'!E40="CB","Doublon · Beaune",""),IF('Roulement V2'!F40="CB","Doublon · Dijon",""))} | D10: {=_xlfn.TEXTJOIN(" + ",TRUE,IF('Roulement V2'!G39="CB","Garde · Beaune",""),IF('Roulement V2'!H39="CB","Garde · Dijon",""),IF('Roulement V2'!G40="CB","Doublon · Beaune",""),IF('Roulement V2'!H40="CB","Doublon · Dijon",""))} | E10: {=_xlfn.TEXTJOIN(" + ",TRUE,IF('Roulement V2'!I39="CB","Garde · Beaune",""),IF('Roulement V2'!J39="CB","Garde · Dijon",""),IF('Roulement V2'!I40="CB","Doublon · Beaune",""),IF('Roulement V2'!J40="CB","Doublon · Dijon",""))} | F10: {=_xlfn.TEXTJOIN(" + ",TRUE,IF('Roulement V2'!K39="CB","Garde · Beaune",""),IF('Roulement V2'!L39="CB","Garde · Dijon",""),IF('Roulement V2'!K40="CB","Doublon · Beaune",""),IF('Roulement V2'!L40="CB","Doublon · Dijon",""))} -> Garde · Dijon | G10: {=_xlfn.TEXTJOIN(" + ",TRUE,IF('Roulement V2'!M39="CB","Garde · Beaune",""),IF('Roulement V2'!N39="CB","Garde · Dijon",""),IF('Roulement V2'!M40="CB","Doublon · Beaune",""),IF('Roulement V2'!N40="CB","Doublon · Dijon",""))} | H10: {=_xlfn.TEXTJOIN(" + ",TRUE,IF('Roulement V2'!O39="CB","Garde · Beaune",""),IF('Roulement V2'!P39="CB","Garde · Dijon",""),IF('Roulement V2'!O40="CB","Doublon · Beaune",""),IF('Roulement V2'!P40="CB","Doublon · Dijon",""))} | I10: {=_xlfn.TEXTJOIN(" + ",TRUE,IF('Roulement V2'!Q39="CB","Garde · Beaune",""),IF('Roulement V2'!R39="CB","Garde · Dijon",""),IF('Roulement V2'!Q40="CB","Doublon · Beaune",""),IF('Roulement V2'!R40="CB","Doublon · Dijon",""))}
A11: Dimanche | B11: {=_xlfn.TEXTJOIN(" + ",TRUE,IF('Roulement V2'!C41="CB","Garde · Beaune",""),IF('Roulement V2'!D41="CB","Garde · Dijon",""),IF('Roulement V2'!C42="CB","Doublon · Beaune",""),IF('Roulement V2'!D42="CB","Doublon · Dijon",""))} -> Garde · Beaune | C11: {=_xlfn.TEXTJOIN(" + ",TRUE,IF('Roulement V2'!E41="CB","Garde · Beaune",""),IF('Roulement V2'!F41="CB","Garde · Dijon",""),IF('Roulement V2'!E42="CB","Doublon · Beaune",""),IF('Roulement V2'!F42="CB","Doublon · Dijon",""))} | D11: {=_xlfn.TEXTJOIN(" + ",TRUE,IF('Roulement V2'!G41="CB","Garde · Beaune",""),IF('Roulement V2'!H41="CB","Garde · Dijon",""),IF('Roulement V2'!G42="CB","Doublon · Beaune",""),IF('Roulement V2'!H42="CB","Doublon · Dijon",""))} | E11: {=_xlfn.TEXTJOIN(" + ",TRUE,IF('Roulement V2'!I41="CB","Garde · Beaune",""),IF('Roulement V2'!J41="CB","Garde · Dijon",""),IF('Roulement V2'!I42="CB","Doublon · Beaune",""),IF('Roulement V2'!J42="CB","Doublon · Dijon",""))} | F11: {=_xlfn.TEXTJOIN(" + ",TRUE,IF('Roulement V2'!K41="CB","Garde · Beaune",""),IF('Roulement V2'!L41="CB","Garde · Dijon",""),IF('Roulement V2'!K42="CB","Doublon · Beaune",""),IF('Roulement V2'!L42="CB","Doublon · Dijon",""))} -> Garde · Dijon | G11: {=_xlfn.TEXTJOIN(" + ",TRUE,IF('Roulement V2'!M41="CB","Garde · Beaune",""),IF('Roulement V2'!N41="CB","Garde · Dijon",""),IF('Roulement V2'!M42="CB","Doublon · Beaune",""),IF('Roulement V2'!N42="CB","Doublon · Dijon",""))} | H11: {=_xlfn.TEXTJOIN(" + ",TRUE,IF('Roulement V2'!O41="CB","Garde · Beaune",""),IF('Roulement V2'!P41="CB","Garde · Dijon",""),IF('Roulement V2'!O42="CB","Doublon · Beaune",""),IF('Roulement V2'!P42="CB","Doublon · Dijon",""))} | I11: {=_xlfn.TEXTJOIN(" + ",TRUE,IF('Roulement V2'!Q41="CB","Garde · Beaune",""),IF('Roulement V2'!R41="CB","Garde · Dijon",""),IF('Roulement V2'!Q42="CB","Doublon · Beaune",""),IF('Roulement V2'!R42="CB","Doublon · Dijon",""))}
A14: Récapitulatif — sur 8 semaines (mise à jour automatique)
A15: J1 · 8h-16h | B15: {=COUNTIF(B5:I9,"*J1 · 8h-16h*")} -> 0 | D15: Beaune | E15: {=COUNTIF(B5:I9,"*Beaune*")} -> 0
A16: J2 · 14h-22h | B16: {=COUNTIF(B5:I9,"*J2 · 14h-22h*")} -> 0 | D16: Dijon | E16: {=COUNTIF(B5:I9,"*Dijon*")} -> 0
A17: Journée · 8h-18h30 | B17: {=COUNTIF(B5:I9,"*journée · 8h-18h30*")} -> 0
A18: Total semaine | B18: {=COUNTIF(B5:I9,"?*")} -> 0 | D18: Gardes WE | E18: {=COUNTIF(B10:I11,"*Garde*")} -> 4
D19: Doublons WE | E19: {=COUNTIF(B10:I11,"*Doublon*")} -> 0

Sheet Imane El Gari
A1: Planning V2 — Imane El Gari (IEG)
A2: Roulement sur 8 semaines · lié à la feuille "Roulement V2" (mise à jour automatique)
A4: Jour | B4: S1 | C4: S2 | D4: S3 | E4: S4 | F4: S5 | G4: S6 | H4: S7 | I4: S8
A5: Lundi
A6: Mardi
A7: Mercredi
A8: Jeudi
A9: vendredi
A10: Samedi | B10: {=_xlfn.TEXTJOIN(" + ",TRUE,IF('Roulement V2'!C39="IEG","Garde · Beaune",""),IF('Roulement V2'!D39="IEG","Garde · Dijon",""),IF('Roulement V2'!C40="IEG","Doublon · Beaune",""),IF('Roulement V2'!D40="IEG","Doublon · Dijon",""))} | C10: {=_xlfn.TEXTJOIN(" + ",TRUE,IF('Roulement V2'!E39="IEG","Garde · Beaune",""),IF('Roulement V2'!F39="IEG","Garde · Dijon",""),IF('Roulement V2'!E40="IEG","Doublon · Beaune",""),IF('Roulement V2'!F40="IEG","Doublon · Dijon",""))} | D10: {=_xlfn.TEXTJOIN(" + ",TRUE,IF('Roulement V2'!G39="IEG","Garde · Beaune",""),IF('Roulement V2'!H39="IEG","Garde · Dijon",""),IF('Roulement V2'!G40="IEG","Doublon · Beaune",""),IF('Roulement V2'!H40="IEG","Doublon · Dijon",""))} | E10: {=_xlfn.TEXTJOIN(" + ",TRUE,IF('Roulement V2'!I39="IEG","Garde · Beaune",""),IF('Roulement V2'!J39="IEG","Garde · Dijon",""),IF('Roulement V2'!I40="IEG","Doublon · Beaune",""),IF('Roulement V2'!J40="IEG","Doublon · Dijon",""))} -> Garde · Beaune | F10: {=_xlfn.TEXTJOIN(" + ",TRUE,IF('Roulement V2'!K39="IEG","Garde · Beaune",""),IF('Roulement V2'!L39="IEG","Garde · Dijon",""),IF('Roulement V2'!K40="IEG","Doublon · Beaune",""),IF('Roulement V2'!L40="IEG","Doublon · Dijon",""))} -> Doublon · Beaune | G10: {=_xlfn.TEXTJOIN(" + ",TRUE,IF('Roulement V2'!M39="IEG","Garde · Beaune",""),IF('Roulement V2'!N39="IEG","Garde · Dijon",""),IF('Roulement V2'!M40="IEG","Doublon · Beaune",""),IF('Roulement V2'!N40="IEG","Doublon · Dijon",""))} | H10: {=_xlfn.TEXTJOIN(" + ",TRUE,IF('Roulement V2'!O39="IEG","Garde · Beaune",""),IF('Roulement V2'!P39="IEG","Garde · Dijon",""),IF('Roulement V2'!O40="IEG","Doublon · Beaune",""),IF('Roulement V2'!P40="IEG","Doublon · Dijon",""))} | I10: {=_xlfn.TEXTJOIN(" + ",TRUE,IF('Roulement V2'!Q39="IEG","Garde · Beaune",""),IF('Roulement V2'!R39="IEG","Garde · Dijon",""),IF('Roulement V2'!Q40="IEG","Doublon · Beaune",""),IF('Roulement V2'!R40="IEG","Doublon · Dijon",""))} -> Doublon · Beaune
A11: Dimanche | B11: {=_xlfn.TEXTJOIN(" + ",TRUE,IF('Roulement V2'!C41="IEG","Garde · Beaune",""),IF('Roulement V2'!D41="IEG","Garde · Dijon",""),IF('Roulement V2'!C42="IEG","Doublon · Beaune",""),IF('Roulement V2'!D42="IEG","Doublon · Dijon",""))} | C11: {=_xlfn.TEXTJOIN(" + ",TRUE,IF('Roulement V2'!E41="IEG","Garde · Beaune",""),IF('Roulement V2'!F41="IEG","Garde · Dijon",""),IF('Roulement V2'!E42="IEG","Doublon · Beaune",""),IF('Roulement V2'!F42="IEG","Doublon · Dijon",""))} | D11: {=_xlfn.TEXTJOIN(" + ",TRUE,IF('Roulement V2'!G41="IEG","Garde · Beaune",""),IF('Roulement V2'!H41="IEG","Garde · Dijon",""),IF('Roulement V2'!G42="IEG","Doublon · Beaune",""),IF('Roulement V2'!H42="IEG","Doublon · Dijon",""))} | E11: {=_xlfn.TEXTJOIN(" + ",TRUE,IF('Roulement V2'!I41="IEG","Garde · Beaune",""),IF('Roulement V2'!J41="IEG","Garde · Dijon",""),IF('Roulement V2'!I42="IEG","Doublon · Beaune",""),IF('Roulement V2'!J42="IEG","Doublon · Dijon",""))} -> Garde · Beaune | F11: {=_xlfn.TEXTJOIN(" + ",TRUE,IF('Roulement V2'!K41="IEG","Garde · Beaune",""),IF('Roulement V2'!L41="IEG","Garde · Dijon",""),IF('Roulement V2'!K42="IEG","Doublon · Beaune",""),IF('Roulement V2'!L42="IEG","Doublon · Dijon",""))} | G11: {=_xlfn.TEXTJOIN(" + ",TRUE,IF('Roulement V2'!M41="IEG","Garde · Beaune",""),IF('Roulement V2'!N41="IEG","Garde · Dijon",""),IF('Roulement V2'!M42="IEG","Doublon · Beaune",""),IF('Roulement V2'!N42="IEG","Doublon · Dijon",""))} | H11: {=_xlfn.TEXTJOIN(" + ",TRUE,IF('Roulement V2'!O41="IEG","Garde · Beaune",""),IF('Roulement V2'!P41="IEG","Garde · Dijon",""),IF('Roulement V2'!O42="IEG","Doublon · Beaune",""),IF('Roulement V2'!P42="IEG","Doublon · Dijon",""))} | I11: {=_xlfn.TEXTJOIN(" + ",TRUE,IF('Roulement V2'!Q41="IEG","Garde · Beaune",""),IF('Roulement V2'!R41="IEG","Garde · Dijon",""),IF('Roulement V2'!Q42="IEG","Doublon · Beaune",""),IF('Roulement V2'!R42="IEG","Doublon · Dijon",""))} -> Doublon · Beaune
A14: Récapitulatif — sur 8 semaines (mise à jour automatique)
A15: J1 · 8h-16h | B15: {=COUNTIF(B5:I9,"*J1 · 8h-16h*")} -> 0 | D15: Beaune | E15: {=COUNTIF(B5:I9,"*Beaune*")} -> 0
A16: J2 · 14h-22h | B16: {=COUNTIF(B5:I9,"*J2 · 14h-22h*")} -> 0 | D16: Dijon | E16: {=COUNTIF(B5:I9,"*Dijon*")} -> 0
A17: Journée · 8h-18h30 | B17: {=COUNTIF(B5:I9,"*journée · 8h-18h30*")} -> 0
A18: Total semaine | B18: {=COUNTIF(B5:I9,"?*")} -> 0 | D18: Gardes WE | E18: {=COUNTIF(B10:I11,"*Garde*")} -> 2
D19: Doublons WE | E19: {=COUNTIF(B10:I11,"*Doublon*")} -> 3

Sheet Laurène Daudin
A1: Planning V2 — Laurène Daudin (LD)
A2: Roulement sur 8 semaines · lié à la feuille "Roulement V2" (mise à jour automatique)
A4: Jour | B4: S1 | C4: S2 | D4: S3 | E4: S4 | F4: S5 | G4: S6 | H4: S7 | I4: S8
A5: Lundi
A6: Mardi
A7: Mercredi
A8: Jeudi
A9: vendredi
A10: Samedi | B10: {=_xlfn.TEXTJOIN(" + ",TRUE,IF('Roulement V2'!C39="LD","Garde · Beaune",""),IF('Roulement V2'!D39="LD","Garde · Dijon",""),IF('Roulement V2'!C40="LD","Doublon · Beaune",""),IF('Roulement V2'!D40="LD","Doublon · Dijon",""))} | C10: {=_xlfn.TEXTJOIN(" + ",TRUE,IF('Roulement V2'!E39="LD","Garde · Beaune",""),IF('Roulement V2'!F39="LD","Garde · Dijon",""),IF('Roulement V2'!E40="LD","Doublon · Beaune",""),IF('Roulement V2'!F40="LD","Doublon · Dijon",""))} -> Doublon · Beaune | D10: {=_xlfn.TEXTJOIN(" + ",TRUE,IF('Roulement V2'!G39="LD","Garde · Beaune",""),IF('Roulement V2'!H39="LD","Garde · Dijon",""),IF('Roulement V2'!G40="LD","Doublon · Beaune",""),IF('Roulement V2'!H40="LD","Doublon · Dijon",""))} | E10: {=_xlfn.TEXTJOIN(" + ",TRUE,IF('Roulement V2'!I39="LD","Garde · Beaune",""),IF('Roulement V2'!J39="LD","Garde · Dijon",""),IF('Roulement V2'!I40="LD","Doublon · Beaune",""),IF('Roulement V2'!J40="LD","Doublon · Dijon",""))} | F10: {=_xlfn.TEXTJOIN(" + ",TRUE,IF('Roulement V2'!K39="LD","Garde · Beaune",""),IF('Roulement V2'!L39="LD","Garde · Dijon",""),IF('Roulement V2'!K40="LD","Doublon · Beaune",""),IF('Roulement V2'!L40="LD","Doublon · Dijon",""))} | G10: {=_xlfn.TEXTJOIN(" + ",TRUE,IF('Roulement V2'!M39="LD","Garde · Beaune",""),IF('Roulement V2'!N39="LD","Garde · Dijon",""),IF('Roulement V2'!M40="LD","Doublon · Beaune",""),IF('Roulement V2'!N40="LD","Doublon · Dijon",""))} -> Doublon · Dijon | H10: {=_xlfn.TEXTJOIN(" + ",TRUE,IF('Roulement V2'!O39="LD","Garde · Beaune",""),IF('Roulement V2'!P39="LD","Garde · Dijon",""),IF('Roulement V2'!O40="LD","Doublon · Beaune",""),IF('Roulement V2'!P40="LD","Doublon · Dijon",""))} | I10: {=_xlfn.TEXTJOIN(" + ",TRUE,IF('Roulement V2'!Q39="LD","Garde · Beaune",""),IF('Roulement V2'!R39="LD","Garde · Dijon",""),IF('Roulement V2'!Q40="LD","Doublon · Beaune",""),IF('Roulement V2'!R40="LD","Doublon · Dijon",""))}
A11: Dimanche | B11: {=_xlfn.TEXTJOIN(" + ",TRUE,IF('Roulement V2'!C41="LD","Garde · Beaune",""),IF('Roulement V2'!D41="LD","Garde · Dijon",""),IF('Roulement V2'!C42="LD","Doublon · Beaune",""),IF('Roulement V2'!D42="LD","Doublon · Dijon",""))} | C11: {=_xlfn.TEXTJOIN(" + ",TRUE,IF('Roulement V2'!E41="LD","Garde · Beaune",""),IF('Roulement V2'!F41="LD","Garde · Dijon",""),IF('Roulement V2'!E42="LD","Doublon · Beaune",""),IF('Roulement V2'!F42="LD","Doublon · Dijon",""))} -> Doublon · Beaune | D11: {=_xlfn.TEXTJOIN(" + ",TRUE,IF('Roulement V2'!G41="LD","Garde · Beaune",""),IF('Roulement V2'!H41="LD","Garde · Dijon",""),IF('Roulement V2'!G42="LD","Doublon · Beaune",""),IF('Roulement V2'!H42="LD","Doublon · Dijon",""))} | E11: {=_xlfn.TEXTJOIN(" + ",TRUE,IF('Roulement V2'!I41="LD","Garde · Beaune",""),IF('Roulement V2'!J41="LD","Garde · Dijon",""),IF('Roulement V2'!I42="LD","Doublon · Beaune",""),IF('Roulement V2'!J42="LD","Doublon · Dijon",""))} | F11: {=_xlfn.TEXTJOIN(" + ",TRUE,IF('Roulement V2'!K41="LD","Garde · Beaune",""),IF('Roulement V2'!L41="LD","Garde · Dijon",""),IF('Roulement V2'!K42="LD","Doublon · Beaune",""),IF('Roulement V2'!L42="LD","Doublon · Dijon",""))} | G11: {=_xlfn.TEXTJOIN(" + ",TRUE,IF('Roulement V2'!M41="LD","Garde · Beaune",""),IF('Roulement V2'!N41="LD","Garde · Dijon",""),IF('Roulement V2'!M42="LD","Doublon · Beaune",""),IF('Roulement V2'!N42="LD","Doublon · Dijon",""))} -> Doublon · Dijon | H11: {=_xlfn.TEXTJOIN(" + ",TRUE,IF('Roulement V2'!O41="LD","Garde · Beaune",""),IF('Roulement V2'!P41="LD","Garde · Dijon",""),IF('Roulement V2'!O42="LD","Doublon · Beaune",""),IF('Roulement V2'!P42="LD","Doublon · Dijon",""))} | I11: {=_xlfn.TEXTJOIN(" + ",TRUE,IF('Roulement V2'!Q41="LD","Garde · Beaune",""),IF('Roulement V2'!R41="LD","Garde · Dijon",""),IF('Roulement V2'!Q42="LD","Doublon · Beaune",""),IF('Roulement V2'!R42="LD","Doublon · Dijon",""))}
A14: Récapitulatif — sur 8 semaines (mise à jour automatique)
A15: J1 · 8h-16h | B15: {=COUNTIF(B5:I9,"*J1 · 8h-16h*")} -> 0 | D15: Beaune | E15: {=COUNTIF(B5:I9,"*Beaune*")} -> 0
A16: J2 · 14h-22h | B16: {=COUNTIF(B5:I9,"*J2 · 14h-22h*")} -> 0 | D16: Dijon | E16: {=COUNTIF(B5:I9,"*Dijon*")} -> 0
A17: Journée · 8h-18h30 | B17: {=COUNTIF(B5:I9,"*journée · 8h-18h30*")} -> 0
A18: Total semaine | B18: {=COUNTIF(B5:I9,"?*")} -> 0 | D18: Gardes WE | E18: {=COUNTIF(B10:I11,"*Garde*")} -> 0
D19: Doublons WE | E19: {=COUNTIF(B10:I11,"*Doublon*")} -> 4

Sheet Mireille Yuan
A1: Planning V2 — Mireille Yuan (MY)
A2: Roulement sur 8 semaines · lié à la feuille "Roulement V2" (mise à jour automatique)
A4: Jour | B4: S1 | C4: S2 | D4: S3 | E4: S4 | F4: S5 | G4: S6 | H4: S7 | I4: S8
A5: Lundi
A6: Mardi
A7: Mercredi
A8: Jeudi
A9: vendredi
A10: Samedi | B10: {=_xlfn.TEXTJOIN(" + ",TRUE,IF('Roulement V2'!C39="MY","Garde · Beaune",""),IF('Roulement V2'!D39="MY","Garde · Dijon",""),IF('Roulement V2'!C40="MY","Doublon · Beaune",""),IF('Roulement V2'!D40="MY","Doublon · Dijon",""))} | C10: {=_xlfn.TEXTJOIN(" + ",TRUE,IF('Roulement V2'!E39="MY","Garde · Beaune",""),IF('Roulement V2'!F39="MY","Garde · Dijon",""),IF('Roulement V2'!E40="MY","Doublon · Beaune",""),IF('Roulement V2'!F40="MY","Doublon · Dijon",""))} | D10: {=_xlfn.TEXTJOIN(" + ",TRUE,IF('Roulement V2'!G39="MY","Garde · Beaune",""),IF('Roulement V2'!H39="MY","Garde · Dijon",""),IF('Roulement V2'!G40="MY","Doublon · Beaune",""),IF('Roulement V2'!H40="MY","Doublon · Dijon",""))} | E10: {=_xlfn.TEXTJOIN(" + ",TRUE,IF('Roulement V2'!I39="MY","Garde · Beaune",""),IF('Roulement V2'!J39="MY","Garde · Dijon",""),IF('Roulement V2'!I40="MY","Doublon · Beaune",""),IF('Roulement V2'!J40="MY","Doublon · Dijon",""))} -> Garde · Dijon | F10: {=_xlfn.TEXTJOIN(" + ",TRUE,IF('Roulement V2'!K39="MY","Garde · Beaune",""),IF('Roulement V2'!L39="MY","Garde · Dijon",""),IF('Roulement V2'!K40="MY","Doublon · Beaune",""),IF('Roulement V2'!L40="MY","Doublon · Dijon",""))} | G10: {=_xlfn.TEXTJOIN(" + ",TRUE,IF('Roulement V2'!M39="MY","Garde · Beaune",""),IF('Roulement V2'!N39="MY","Garde · Dijon",""),IF('Roulement V2'!M40="MY","Doublon · Beaune",""),IF('Roulement V2'!N40="MY","Doublon · Dijon",""))} | H10: {=_xlfn.TEXTJOIN(" + ",TRUE,IF('Roulement V2'!O39="MY","Garde · Beaune",""),IF('Roulement V2'!P39="MY","Garde · Dijon",""),IF('Roulement V2'!O40="MY","Doublon · Beaune",""),IF('Roulement V2'!P40="MY","Doublon · Dijon",""))} | I10: {=_xlfn.TEXTJOIN(" + ",TRUE,IF('Roulement V2'!Q39="MY","Garde · Beaune",""),IF('Roulement V2'!R39="MY","Garde · Dijon",""),IF('Roulement V2'!Q40="MY","Doublon · Beaune",""),IF('Roulement V2'!R40="MY","Doublon · Dijon",""))} -> Garde · Beaune
A11: Dimanche | B11: {=_xlfn.TEXTJOIN(" + ",TRUE,IF('Roulement V2'!C41="MY","Garde · Beaune",""),IF('Roulement V2'!D41="MY","Garde · Dijon",""),IF('Roulement V2'!C42="MY","Doublon · Beaune",""),IF('Roulement V2'!D42="MY","Doublon · Dijon",""))} | C11: {=_xlfn.TEXTJOIN(" + ",TRUE,IF('Roulement V2'!E41="MY","Garde · Beaune",""),IF('Roulement V2'!F41="MY","Garde · Dijon",""),IF('Roulement V2'!E42="MY","Doublon · Beaune",""),IF('Roulement V2'!F42="MY","Doublon · Dijon",""))} | D11: {=_xlfn.TEXTJOIN(" + ",TRUE,IF('Roulement V2'!G41="MY","Garde · Beaune",""),IF('Roulement V2'!H41="MY","Garde · Dijon",""),IF('Roulement V2'!G42="MY","Doublon · Beaune",""),IF('Roulement V2'!H42="MY","Doublon · Dijon",""))} | E11: {=_xlfn.TEXTJOIN(" + ",TRUE,IF('Roulement V2'!I41="MY","Garde · Beaune",""),IF('Roulement V2'!J41="MY","Garde · Dijon",""),IF('Roulement V2'!I42="MY","Doublon · Beaune",""),IF('Roulement V2'!J42="MY","Doublon · Dijon",""))} -> Garde · Dijon | F11: {=_xlfn.TEXTJOIN(" + ",TRUE,IF('Roulement V2'!K41="MY","Garde · Beaune",""),IF('Roulement V2'!L41="MY","Garde · Dijon",""),IF('Roulement V2'!K42="MY","Doublon · Beaune",""),IF('Roulement V2'!L42="MY","Doublon · Dijon",""))} | G11: {=_xlfn.TEXTJOIN(" + ",TRUE,IF('Roulement V2'!M41="MY","Garde · Beaune",""),IF('Roulement V2'!N41="MY","Garde · Dijon",""),IF('Roulement V2'!M42="MY","Doublon · Beaune",""),IF('Roulement V2'!N42="MY","Doublon · Dijon",""))} | H11: {=_xlfn.TEXTJOIN(" + ",TRUE,IF('Roulement V2'!O41="MY","Garde · Beaune",""),IF('Roulement V2'!P41="MY","Garde · Dijon",""),IF('Roulement V2'!O42="MY","Doublon · Beaune",""),IF('Roulement V2'!P42="MY","Doublon · Dijon",""))} | I11: {=_xlfn.TEXTJOIN(" + ",TRUE,IF('Roulement V2'!Q41="MY","Garde · Beaune",""),IF('Roulement V2'!R41="MY","Garde · Dijon",""),IF('Roulement V2'!Q42="MY","Doublon · Beaune",""),IF('Roulement V2'!R42="MY","Doublon · Dijon",""))} -> Garde · Beaune
A14: Récapitulatif — sur 8 semaines (mise à jour automatique)
A15: J1 · 8h-16h | B15: {=COUNTIF(B5:I9,"*J1 · 8h-16h*")} -> 0 | D15: Beaune | E15: {=COUNTIF(B5:I9,"*Beaune*")} -> 0
A16: J2 · 14h-22h | B16: {=COUNTIF(B5:I9,"*J2 · 14h-22h*")} -> 0 | D16: Dijon | E16: {=COUNTIF(B5:I9,"*Dijon*")} -> 0
A17: Journée · 8h-18h30 | B17: {=COUNTIF(B5:I9,"*journée · 8h-18h30*")} -> 0
A18: Total semaine | B18: {=COUNTIF(B5:I9,"?*")} -> 0 | D18: Gardes WE | E18: {=COUNTIF(B10:I11,"*Garde*")} -> 4
D19: Doublons WE | E19: {=COUNTIF(B10:I11,"*Doublon*")} -> 0
